Workbook

Sheet FormatCodesSFX
A3: The CELL function returns | B3: Display
A4: ,0 | B4: comma format with 0 decimal places
A5: ,0- | B5: comma format with 0 decimal places, negative numbers in red
A6: ,1 | B6: comma format with 1 decimal places
A7: ,1- | B7: comma format with 1 decimal places, negative numbers in red
A8: ,2 | B8: comma format with 2 decimal places
A9: ,2- | B9: comma format with 2 decimal places, negative numbers in red
A10: ,3 | B10: comma format with 3 decimal places
A11: ,3- | B11: comma format with 3 decimal places, negative numbers in red
A12: ,4 | B12: comma format with 4 decimal places
A13: ,4- | B13: comma format with 4 decimal places, negative numbers in red
A14: C0 | B14: currency/accounting with 0 decimal places
... A53: S4 | B53: scientific with 4 decimal places

Sheet FeedbackSFX
A1: Rand | B1: =RANDBETWEEN(3,9) -> 6
A2: Code | B2: StuNAMsg | C2: PerfectMsg | D2: StuErrorMsg | E2: WrongTypeMsg | F2: MissingFormulaMsg | G2: ExternalRefsMsg | H2: HardCodeMsg | I2: HardQuoteMsg | J2: MissingAbsMsg | K2: FormatMsg | L2: TooLow | M2: TooHigh | N2: WrongAnswer
A3: Standard Message | B3: ERROR--#N/A means that no value was found, but there should be one. Please correct. | C3: PERFECT! | D3: ERROR--Please change the formula or function to eliminate the error. | E3: WRONG DATATYPE--Please change your answer to match the datatype listed above. | F3: MISSING FORMULA or FUNCTION--Please avoid typing an answer that can be calculated. Typed answers are error-prone, hard to audit, and hard to update. | G3: ERROR--Formula copied from another workbook. | H3: MISSING CELL REFERENCE--Right answer but please avoid typing numbers inside a formula or function. | I3: MISSING CELL REFERENCE--Right answer but please avoid typing text inside a formula or function. | J3: MISSING LOCK--Please add $ as appropriate so the formula will copy correctly. | K3: WRONG FORMAT--Please format as directed, then press F9 (or fn + F9) to regrade. | L3: Value too low, please try again. | M3: Value too high, please try again. | N3: Wrong answer, please try again.
A4: Funny Messages | B4: Oops! N/A found – formula missing its mark! 🎯❌ | C4: AWESOME! 🤓 | D4: Cell adrift in Error Sea. 🌊 Chart a formula fix! 🧭 | E4: Love Island error! Set up your data with the right datatype match. 💔🔄 | F4: Houston, formula required for this mission! 🚀🧩 | G4: Ouch! Cell caught referencing the workbook next door! 😣📚 | H4: Missed cell refs? Swap those numbers for proper invites! 📲➡️🎯 | I4: Missed cell refs? Swap that text for proper invites! _xD83D_➡️🎯 | J4: Unlocked cells? Add $ to ensure they copy correctly! 🔒➡️📄 | K4: Wrong number attire? Reformat, then F9 (or fn + F9)!⚙️ | L4: Too low, boost that number! 🔼 | M4: Too high, lower that number! 🔽 | N4: Seriously? Nope. Try again! 🙄🔄
B5: N/A signal! Did your formula forget something? 🤔🚦 | C5: EXCELLENT! 🤑 | D5: Formula Error Monster! 👾 Cast a fix-it spell. 🪄 | E5: Identity crisis in cell! Guide it to its true datatype. 🆔➡️🔧 | F5: Formula MIA? Let's launch a search! 🔍🛰 | G5: Cell's got a roving eye for other workbooks! Commitment time? 💍📁 | H5: Cell FOMO? Time to party with the right references! 🥳🔗 | I5: Cell FOMO? Time to party with the right references! 🥳🔗 | J5: Cells escaping when copied? $ is the key to containment! 🗝️🔐 | K5: Unkempt number? Reformat, then F9 (or fn + F9)! 🎩✨ | L5: Valley too deep? Raise the number! ⬆️🏞️ | M5: Sky-high value? Bring it down! ⬇️🌤️ | N5: Nope, that ain’t it. What’s next? ❌🤨
B6: #N/A in hideout, send formula back to search! 🔍🏹 | C6: YOU'RE CRUSHING IT! Keep that greatness coming! 💪✨ | D6: Formula fail! 🚨 Call the math-mobile for a recalc! 🚗 | E6: Mismatch alert! This isn't a mix-and-match. Align your datatypes. 🚫❌ | F6: Cell's bare! Quick, clothe it with a formula! 👚✨ | G6: Workbook envy? This cell's a one-book wonder! 😒🔒 | H6: Friends > numbers. Replace typed digits with cell pals! 🤝📊 | I6: Friends > text. Replace text with cell pals! 🤝📊 | J6: Spreadsheet anarchy? Use $ to copy cells without mayhem! 🔄🚫 | K6: Number's style off? Reformat, then F9 (or fn + F9) to fix! 👗🔄 | L6: Bottom feeder? Not this time—larger number needed. 📈 | M6: Top-shelf number? Time for a lower shelf. 📉 | N6: Wrong. Take another stab. 🎯👀
B7: N/A detected! Command your formula to find the value! 🎮🕹 | C7: STELLAR PERFORMANCE! The stars have nothing on you! 🌟🚀 | D7: Game on! 🎮 Hunt for the error-busting formula. 🔍 | E7: Data type mismatch! Swipe right on the correct datatype. 👈👉📲 | F7: Formula's gone poof! Time for a magic formula fix! 🪄📈 | G7: Cell fidelity: It's exclusive with our workbook! 🚫📖💕 | H7: Lonely numbers? Unite them with cell reference friends! 👯‍♂️🔢 | I7: Lonely text? Unite it with cell reference friends! 👯‍♂️🔢 | J7: Cells drifting during copy? $ will pin them in place! 📌📋 | K7: Make the number pretty! Reformat, then F9 (or fn + F9) for shine! 💅🔁 | L7: Limbo number? Go higher, please. 🏋️‍♂️ | M7: Number too tall? Bend it down a notch. _xD83D_⬇️ | N7: Uh-oh, swing and a miss! Focus and retry. ⚾️🧐
B8: N/A – a lonely cell where your formula lost its way! 🧭💔 | C8: A ROUND OF APPLAUSE! Your work deserves an encore! 👏👏🎉 | D8: Your formula's flipping out! 🤸‍♂️ Coach it to stick the landing. 🎖️ | E8: Costume mix-up! Your data needs to change into the correct datatype. 🎭✅ | F8: This cell's single, introduce it to a formula? 💔🧮 | G8: Forbidden cross-book cell mingling detected! 🙅‍♂️🚷 | H8: Formulas thrive on connections! Link up those cells! 🌐🤲 | I8: Formulas thrive on connections! Link up those cells! 🌐🤲 | J8: Copy chaos? Freeze cells with $, no more moves! ✋🔄 | K8: Number outfit mix-up? Reformat, hit F9 (or fn + F9)! 🧳🔄 | L8: Digging too deep? The correct value's higher up! 🚧⬆️ | M8: Climbing too high? The correct value's down below! 🧗‍♂️⬇️ | N8: That’s a negative. Try again! 🚫🔄
B9: N/A: Value's playing hard to get, or formula faux pas? 🎩🐰 | C9: HOME RUN! You've hit it out of the park! ⚾🏟️ | D9: Jittery cell? 📱 Prescribe a calming formula. 💊 | E9: Wrong type alert! Time for a datatype switcheroo. 🔄🔀 | F9: Forbidden formula zone? Summon the formula wizard! 🧙‍♂️📐 | G9: This cell's heart belongs to its home workbook! 🏠💔📉 | H9: Ditch the DIY. Cells crave references, not solitude! 🧩🔍 | I9: Ditch the DIY. Cells crave references, not solitude! 🧩🔍 | J9: Cells changing on copy? Anchor with $ for consistency! ⚓👌 | K9: Last season's cell? Format, then F9 (or fn + F9)! 🍂🆕 | L9: Basement value? Uplift the value! 🏠⤴️ | M9: Penthouse value? Downsize the digits! 🏢🔻 | N9: Not correct! Try again! 💡🔙
B10: N/A blank... Formula hiccup! Time for a fix-up! 🛠️😅 | C10: Bravo! That's some next-level excellence! 🎭🏆 | D10: Magic mirror says: This formula's not the fairest! 🪞 | E10: Data's two left feet? Find the right datatype dance partner. 💃🕺🎶 | F10: Cell playing hooky? Detention with a formula tutor! 🍎📖 | G10: Cell wanderlust? No, keep its formulas in this workbook's embrace! 🌍✋🔐 | H10: Solo formula? Add some cell reference company! 🎉📑 | I10: Solo formula? Add some cell reference company! 🎉📑 | J10: Copying cells gone rogue? Reinforce with $ for precision! 🎯💲 | K10: Format violation? Reformat, then F9 (or fn + F9)! 🚦👔 | L10: Number's too deep? Bring it up for air! 🌊🆙 | M10: Number's in the clouds? Land it gently! ☁️🛬 | N10: Incorrect! You can do better, redo! 🔄💪

Sheet Scoreboard
B2: ScoreBoard for Excel | I2: =$B$23&"/"&$C$23 -> 0/176
B3: Have fun. Don't Fail. | I3: =$D$23 -> 0
B4: Automated grading and feedback copyright ScoreboardExcel.com ©2025 | E4: =IFERROR(_xlfn.CONCAT("Excel version: ",INFO("release")),"Excel version: Invalid") -> Excel version: 16.0 | F4: {=IFERROR(IF(OR(ISERROR(_xlfn.RANDARRAY()), ISERROR(INFO("osversion"))), "Error: Please use Office 2021 desktop version or newer", _xlfn.CONCAT("Operating system: ", INFO("osversion"))),"Error: Please use Office 2021 desktop version or newer")} -> Operating system: Windows (32-bit) NT 10.00
B6: key_intromis-1-a_1PV
B7: Business Analytics with Excel
B8: Prof. Bartosiak | C8: =IF(OR($E$4="Excel version: Invalid", $F$4="Error: Please use Office 2021 desktop version or newer"), "****Error: Please use Office 2021 desktop version or newer****", "") | I8: 45986
B9: University of Pavia
B12: Earn points by completing shaded cells; higher value cells have distinct borders | F12: 1 | G12: 0.5 | H12: 1
B14: Answer blocks are all or nothing; correctly complete all contributing cells to earn points:
B16: If you accidentally drag a cell out of position, then undo. Do NOT try to drag it back. | F16: 5
B19: Detailed Feedback:
B20: Earned | C20: Possible | D20: Sheet | E20: Comment
B21: =IF(Sheet1SC!$A$2="","locked",Sheet1SC!$A$2) -> 0 | C21: =Sheet1SC!$B$2 -> 176 | D21: Sheet1 | F21: {=_xlfn.IFS(ROW(Sheet1!A100)<100,"A row has been deleted",COLUMN(Sheet1!BB1)<54,"A column has been deleted",ROW(Sheet1!A100)>100,"A row has been inserted",COLUMN(Sheet1!BB1)>54,"A column has been inserted",TRUE=TRUE,"")}
B23: =SUM(B21:B21) -> 0 | C23: =SUM(C21:C21) -> 176 | D23: =IFERROR(ROUNDUP($B$23/$C$23,3),0) -> 0
B35: This assignment was created by Scoreboard Excel 13.54.

Sheet Sheet1PT
A3: 1 | B3: 1 | C3: 1 | D3: 1 | E3: 1 | F3: 1 | G3: 1 | H3: 1
A4: 1 | B4: 1 | C4: 1 | D4: 1 | E4: 1 | F4: 1 | G4: 1 | H4: 1
A5: 1 | B5: 1 | C5: 1 | D5: 1 | E5: 1 | F5: 1 | G5: 1 | H5: 0
A6: 1 | B6: 1 | C6: 1 | D6: 1 | E6: 1 | F6: 1 | G6: 1 | H6: 0
A7: 1 | B7: 1 | C7: 1 | D7: 1 | E7: 1 | F7: 1 | G7: 1 | H7: 0
A8: 1 | B8: 1 | C8: 1 | D8: 1 | E8: 1 | F8: 1 | G8: 1 | H8: 0
A9: 1 | B9: 1 | C9: 1 | D9: 1 | E9: 1 | F9: 1 | G9: 1 | H9: 0
A10: 1 | B10: 1 | C10: 1 | D10: 1 | E10: 1 | F10: 1 | G10: 1 | H10: 0
A11: 1 | B11: 1 | C11: 1 | D11: 1 | E11: 1 | F11: 1 | G11: 1 | H11: 0
A12: 1 | B12: 1 | C12: 1 | D12: 1 | E12: 1 | F12: 1 | G12: 1 | H12: 0
A13: 1 | B13: 1 | C13: 1 | D13: 1 | E13: 1 | F13: 1 | G13: 1 | H13: 0
A14: 1 | B14: 1 | C14: 1 | D14: 1 | E14: 1 | F14: 1 | G14: 1 | H14: 0
... A28: 0 | B28: 0 | C28: 0 | D28: 0 | E28: 0 | F28: 0 | G28: 0 | H28: 0

Sheet Sheet1SC
A2: =IF(Sheet1!$D$2="DRAGGING CELLS IS NOT PERMITTED. PLEASE UNDO LAST ACTION!!",0,IF(Sheet1!$P$1<>"Feedback OFF",IF(Scoreboard!$F$21="",IFERROR(IF(B2=0,C2,IF(C2/B2>=Scoreboard!$F$19,C2,"")),""),0),0)) -> 0 | B2: =SUMIF(Sheet1PT!A3:$AL$27,">0") -> 176 | C2: =SUMIFS(Sheet1PT!A3:$AL$27, Sheet1PT!A3:$AL$27, ">0", Sheet1SC!A3:$AL$27, "PerfectMsg")+ABS(SUMIFS(Sheet1PT!A3:$AL$27, Sheet1PT!A3:$AL$27, "<0", Sheet1SC!A3:$AL$27, "PerfectMsg")) -> 0
A3: =_xlfn.IFS(ISBLANK(Sheet1!A3),"",IF(NOT(ISNA('#_Sheet1'!A3)),IF(ISNA(Sheet1!A3),TRUE,FALSE),FALSE),"StuNAMsg",IF(AND(ISNA('#_Sheet1'!A3),ISNA(Sheet1!A3)),TRUE,FALSE),"PerfectMsg",IF(NOT(ISERROR('#_Sheet1'!A3)),IF(ISERROR(Sheet1!A3),TRUE,FALSE),FALSE),"StuErrorMsg",IF(TYPE('#_Sheet1'!A3)<>TYPE(Sheet1!A3),TRUE,FALSE),"WrongTypeMsg",IF(ISNUMBER('#_Sheet1'!A3),IF(ABS('#_Sheet1'!A3-Sheet1!A3)>0.00001,TRUE,FALSE),IF('#_Sheet1'!A3<>Sheet1!A3,TRUE,FALSE)),IF(ISNUMBER('#_Sheet1'!A3),IF('#_Sheet1'!A3>Sheet1!A3,"TooLow","TooHigh"),"WrongAnswer"),NOT(_xlfn.ISFORMULA('#_Sheet1'!A3)),IF(_xlfn.IFS(ISTEXT('#_Sheet1'!A3),FALSE,ISLOGICAL('#_Sheet1'!A3),FALSE,SUBSTITUTE(CELL("format",'#_Sheet1'!A3),"-","")=SUBSTITUTE(CELL("format",Sheet1!A3),"-",""),FALSE,CELL("format",'#_Sheet1'!A3)="G",FALSE,AND(CELL("format",'#_Sheet1'!A3)="F0",CELL("format",Sheet1!A3)="G"),FALSE,TRUE,IFERROR(IF(MATCH(CELL("format",'#_Sheet1'!A3),FormatCodesSFX!$A$4:$A$53,0)>0,TRUE),FALSE),TRUE,TRUE),"FormatMsg","PerfectMsg"),_xlfn.IFS(ISTEXT('#_Sheet1'!A3),FALSE,ISLOGICAL('#_Sheet1'!A3),FALSE,SUBSTITUTE(CELL("format",'#_Sheet1'!A3),"-","")=SUBSTITUTE(CELL("format",Sheet1!A3),"-",""),FALSE,CELL("format",'#_Sheet1'!A3)="G",FALSE,AND(CELL("format",'#_Sheet1'!A3)="F0",CELL("format",Sheet1!A3)="G"),FALSE,TRUE,IFERROR(IF(MATCH(CELL("format",'#_Sheet1'!A3),FormatCodesSFX!$A$4:$A$53,0)>0,TRUE),FALSE),TRUE,TRUE),"FormatMsg",TRUE,"PerfectMsg") | B3: =_xlfn.IFS(ISBLANK(Sheet1!B3),"",IF(NOT(ISNA('#_Sheet1'!B3)),IF(ISNA(Sheet1!B3),TRUE,FALSE),FALSE),"StuNAMsg",IF(AND(ISNA('#_Sheet1'!B3),ISNA(Sheet1!B3)),TRUE,FALSE),"PerfectMsg",IF(NOT(ISERROR('#_Sheet1'!B3)),IF(ISERROR(Sheet1!B3),TRUE,FALSE),FALSE),"StuErrorMsg",IF(TYPE('#_Sheet1'!B3)<>TYPE(Sheet1!B3),TRUE,FALSE),"WrongTypeMsg",IF(ISNUMBER('#_Sheet1'!B3),IF(ABS('#_Sheet1'!B3-Sheet1!B3)>0.00001,TRUE,FALSE),IF('#_Sheet1'!B3<>Sheet1!B3,TRUE,FALSE)),IF(ISNUMBER('#_Sheet1'!B3),IF('#_Sheet1'!B3>Sheet1!B3,"TooLow","TooHigh"),"WrongAnswer"),NOT(_xlfn.ISFORMULA('#_Sheet1'!B3)),IF(_xlfn.IFS(ISTEXT('#_Sheet1'!B3),FALSE,ISLOGICAL('#_Sheet1'!B3),FALSE,SUBSTITUTE(CELL("format",'#_Sheet1'!B3),"-","")=SUBSTITUTE(CELL("format",Sheet1!B3),"-",""),FALSE,CELL("format",'#_Sheet1'!B3)="G",FALSE,AND(CELL("format",'#_Sheet1'!B3)="F0",CELL("format",Sheet1!B3)="G"),FALSE,TRUE,IFERROR(IF(MATCH(CELL("format",'#_Sheet1'!B3),FormatCodesSFX!$A$4:$A$53,0)>0,TRUE),FALSE),TRUE,TRUE),"FormatMsg","PerfectMsg"),_xlfn.IFS(ISTEXT('#_Sheet1'!B3),FALSE,ISLOGICAL('#_Sheet1'!B3),FALSE,SUBSTITUTE(CELL("format",'#_Sheet1'!B3),"-","")=SUBSTITUTE(CELL("format",Sheet1!B3),"-",""),FALSE,CELL("format",'#_Sheet1'!B3)="G",FALSE,AND(CELL("format",'#_Sheet1'!B3)="F0",CELL("format",Sheet1!B3)="G"),FALSE,TRUE,IFERROR(IF(MATCH(CELL("format",'#_Sheet1'!B3),FormatCodesSFX!$A$4:$A$53,0)>0,TRUE),FALSE),TRUE,TRUE),"FormatMsg",TRUE,"PerfectMsg") | C3: =_xlfn.IFS(ISBLANK(Sheet1!C3),"",IF(NOT(ISNA('#_Sheet1'!C3)),IF(ISNA(Sheet1!C3),TRUE,FALSE),FALSE),"StuNAMsg",IF(AND(ISNA('#_Sheet1'!C3),ISNA(Sheet1!C3)),TRUE,FALSE),"PerfectMsg",IF(NOT(ISERROR('#_Sheet1'!C3)),IF(ISERROR(Sheet1!C3),TRUE,FALSE),FALSE),"StuErrorMsg",IF(TYPE('#_Sheet1'!C3)<>TYPE(Sheet1!C3),TRUE,FALSE),"WrongTypeMsg",IF(ISNUMBER('#_Sheet1'!C3),IF(ABS('#_Sheet1'!C3-Sheet1!C3)>0.00001,TRUE,FALSE),IF('#_Sheet1'!C3<>Sheet1!C3,TRUE,FALSE)),IF(ISNUMBER('#_Sheet1'!C3),IF('#_Sheet1'!C3>Sheet1!C3,"TooLow","TooHigh"),"WrongAnswer"),NOT(_xlfn.ISFORMULA('#_Sheet1'!C3)),IF(_xlfn.IFS(ISTEXT('#_Sheet1'!C3),FALSE,ISLOGICAL('#_Sheet1'!C3),FALSE,SUBSTITUTE(CELL("format",'#_Sheet1'!C3),"-","")=SUBSTITUTE(CELL("format",Sheet1!C3),"-",""),FALSE,CELL("format",'#_Sheet1'!C3)="G",FALSE,AND(CELL("format",'#_Sheet1'!C3)="F0",CELL("format",Sheet1!C3)="G"),FALSE,TRUE,IFERROR(IF(MATCH(CELL("format",'#_Sheet1'!C3),FormatCodesSFX!$A$4:$A$53,0)>0,TRUE),FALSE),TRUE,TRUE),"FormatMsg","PerfectMsg"),_xlfn.IFS(ISTEXT('#_Sheet1'!C3),FALSE,ISLOGICAL('#_Sheet1'!C3),FALSE,SUBSTITUTE(CELL("format",'#_Sheet1'!C3),"-","")=SUBSTITUTE(CELL("format",Sheet1!C3),"-",""),FALSE,CELL("format",'#_Sheet1'!C3)="G",FALSE,AND(CELL("format",'#_Sheet1'!C3)="F0",CELL("format",Sheet1!C3)="G"),FALSE,TRUE,IFERROR(IF(MATCH(CELL("format",'#_Sheet1'!C3),FormatCodesSFX!$A$4:$A$53,0)>0,TRUE),FALSE),TRUE,TRUE),"FormatMsg",TRUE,"PerfectMsg") | D3: =_xlfn.IFS(ISBLANK(Sheet1!D3),"",IF(NOT(ISNA('#_Sheet1'!D3)),IF(ISNA(Sheet1!D3),TRUE,FALSE),FALSE),"StuNAMsg",IF(AND(ISNA('#_Sheet1'!D3),ISNA(Sheet1!D3)),TRUE,FALSE),"PerfectMsg",IF(NOT(ISERROR('#_Sheet1'!D3)),IF(ISERROR(Sheet1!D3),TRUE,FALSE),FALSE),"StuErrorMsg",IF(TYPE('#_Sheet1'!D3)<>TYPE(Sheet1!D3),TRUE,FALSE),"WrongTypeMsg",IF(ISNUMBER('#_Sheet1'!D3),IF(ABS('#_Sheet1'!D3-Sheet1!D3)>0.00001,TRUE,FALSE),IF('#_Sheet1'!D3<>Sheet1!D3,TRUE,FALSE)),IF(ISNUMBER('#_Sheet1'!D3),IF('#_Sheet1'!D3>Sheet1!D3,"TooLow","TooHigh"),"WrongAnswer"),NOT(_xlfn.ISFORMULA('#_Sheet1'!D3)),IF(_xlfn.IFS(ISTEXT('#_Sheet1'!D3),FALSE,ISLOGICAL('#_Sheet1'!D3),FALSE,SUBSTITUTE(CELL("format",'#_Sheet1'!D3),"-","")=SUBSTITUTE(CELL("format",Sheet1!D3),"-",""),FALSE,CELL("format",'#_Sheet1'!D3)="G",FALSE,AND(CELL("format",'#_Sheet1'!D3)="F0",CELL("format",Sheet1!D3)="G"),FALSE,TRUE,IFERROR(IF(MATCH(CELL("format",'#_Sheet1'!D3),FormatCodesSFX!$A$4:$A$53,0)>0,TRUE),FALSE),TRUE,TRUE),"FormatMsg","PerfectMsg"),_xlfn.IFS(ISTEXT('#_Sheet1'!D3),FALSE,ISLOGICAL('#_Sheet1'!D3),FALSE,SUBSTITUTE(CELL("format",'#_Sheet1'!D3),"-","")=SUBSTITUTE(CELL("format",Sheet1!D3),"-",""),FALSE,CELL("format",'#_Sheet1'!D3)="G",FALSE,AND(CELL("format",'#_Sheet1'!D3)="F0",CELL("format",Sheet1!D3)="G"),FALSE,TRUE,IFERROR(IF(MATCH(CELL("format",'#_Sheet1'!D3),FormatCodesSFX!$A$4:$A$53,0)>0,TRUE),FALSE),TRUE,TRUE),"FormatMsg",TRUE,"PerfectMsg") | E3: =_xlfn.IFS(ISBLANK(Sheet1!E3),"",IF(NOT(ISNA('#_Sheet1'!E3)),IF(ISNA(Sheet1!E3),TRUE,FALSE),FALSE),"StuNAMsg",IF(AND(ISNA('#_Sheet1'!E3),ISNA(Sheet1!E3)),TRUE,FALSE),"PerfectMsg",IF(NOT(ISERROR('#_Sheet1'!E3)),IF(ISERROR(Sheet1!E3),TRUE,FALSE),FALSE),"StuErrorMsg",IF(TYPE('#_Sheet1'!E3)<>TYPE(Sheet1!E3),TRUE,FALSE),"WrongTypeMsg",IF(ISNUMBER('#_Sheet1'!E3),IF(ABS('#_Sheet1'!E3-Sheet1!E3)>0.00001,TRUE,FALSE),IF('#_Sheet1'!E3<>Sheet1!E3,TRUE,FALSE)),IF(ISNUMBER('#_Sheet1'!E3),IF('#_Sheet1'!E3>Sheet1!E3,"TooLow","TooHigh"),"WrongAnswer"),NOT(_xlfn.ISFORMULA('#_Sheet1'!E3)),IF(_xlfn.IFS(ISTEXT('#_Sheet1'!E3),FALSE,ISLOGICAL('#_Sheet1'!E3),FALSE,SUBSTITUTE(CELL("format",'#_Sheet1'!E3),"-","")=SUBSTITUTE(CELL("format",Sheet1!E3),"-",""),FALSE,CELL("format",'#_Sheet1'!E3)="G",FALSE,AND(CELL("format",'#_Sheet1'!E3)="F0",CELL("format",Sheet1!E3)="G"),FALSE,TRUE,IFERROR(IF(MATCH(CELL("format",'#_Sheet1'!E3),FormatCodesSFX!$A$4:$A$53,0)>0,TRUE),FALSE),TRUE,TRUE),"FormatMsg","PerfectMsg"),_xlfn.IFS(ISTEXT('#_Sheet1'!E3),FALSE,ISLOGICAL('#_Sheet1'!E3),FALSE,SUBSTITUTE(CELL("format",'#_Sheet1'!E3),"-","")=SUBSTITUTE(CELL("format",Sheet1!E3),"-",""),FALSE,CELL("format",'#_Sheet1'!E3)="G",FALSE,AND(CELL("format",'#_Sheet1'!E3)="F0",CELL("format",Sheet1!E3)="G"),FALSE,TRUE,IFERROR(IF(MATCH(CELL("format",'#_Sheet1'!E3),FormatCodesSFX!$A$4:$A$53,0)>0,TRUE),FALSE),TRUE,TRUE),"FormatMsg",TRUE,"PerfectMsg") | F3: =_xlfn.IFS(ISBLANK(Sheet1!F3),"",IF(NOT(ISNA('#_Sheet1'!F3)),IF(ISNA(Sheet1!F3),TRUE,FALSE),FALSE),"StuNAMsg",IF(AND(ISNA('#_Sheet1'!F3),ISNA(Sheet1!F3)),TRUE,FALSE),"PerfectMsg",IF(NOT(ISERROR('#_Sheet1'!F3)),IF(ISERROR(Sheet1!F3),TRUE,FALSE),FALSE),"StuErrorMsg",IF(TYPE('#_Sheet1'!F3)<>TYPE(Sheet1!F3),TRUE,FALSE),"WrongTypeMsg",IF(ISNUMBER('#_Sheet1'!F3),IF(ABS('#_Sheet1'!F3-Sheet1!F3)>0.00001,TRUE,FALSE),IF('#_Sheet1'!F3<>Sheet1!F3,TRUE,FALSE)),IF(ISNUMBER('#_Sheet1'!F3),IF('#_Sheet1'!F3>Sheet1!F3,"TooLow","TooHigh"),"WrongAnswer"),NOT(_xlfn.ISFORMULA('#_Sheet1'!F3)),IF(_xlfn.IFS(ISTEXT('#_Sheet1'!F3),FALSE,ISLOGICAL('#_Sheet1'!F3),FALSE,SUBSTITUTE(CELL("format",'#_Sheet1'!F3),"-","")=SUBSTITUTE(CELL("format",Sheet1!F3),"-",""),FALSE,CELL("format",'#_Sheet1'!F3)="G",FALSE,AND(CELL("format",'#_Sheet1'!F3)="F0",CELL("format",Sheet1!F3)="G"),FALSE,TRUE,IFERROR(IF(MATCH(CELL("format",'#_Sheet1'!F3),FormatCodesSFX!$A$4:$A$53,0)>0,TRUE),FALSE),TRUE,TRUE),"FormatMsg","PerfectMsg"),_xlfn.IFS(ISTEXT('#_Sheet1'!F3),FALSE,ISLOGICAL('#_Sheet1'!F3),FALSE,SUBSTITUTE(CELL("format",'#_Sheet1'!F3),"-","")=SUBSTITUTE(CELL("format",Sheet1!F3),"-",""),FALSE,CELL("format",'#_Sheet1'!F3)="G",FALSE,AND(CELL("format",'#_Sheet1'!F3)="F0",CELL("format",Sheet1!F3)="G"),FALSE,TRUE,IFERROR(IF(MATCH(CELL("format",'#_Sheet1'!F3),FormatCodesSFX!$A$4:$A$53,0)>0,TRUE),FALSE),TRUE,TRUE),"FormatMsg",TRUE,"PerfectMsg") | G3: =_xlfn.IFS(ISBLANK(Sheet1!G3),"",IF(NOT(ISNA('#_Sheet1'!G3)),IF(ISNA(Sheet1!G3),TRUE,FALSE),FALSE),"StuNAMsg",IF(AND(ISNA('#_Sheet1'!G3),ISNA(Sheet1!G3)),TRUE,FALSE),"PerfectMsg",IF(NOT(ISERROR('#_Sheet1'!G3)),IF(ISERROR(Sheet1!G3),TRUE,FALSE),FALSE),"StuErrorMsg",IF(TYPE('#_Sheet1'!G3)<>TYPE(Sheet1!G3),TRUE,FALSE),"WrongTypeMsg",IF(ISNUMBER('#_Sheet1'!G3),IF(ABS('#_Sheet1'!G3-Sheet1!G3)>0.00001,TRUE,FALSE),IF('#_Sheet1'!G3<>Sheet1!G3,TRUE,FALSE)),IF(ISNUMBER('#_Sheet1'!G3),IF('#_Sheet1'!G3>Sheet1!G3,"TooLow","TooHigh"),"WrongAnswer"),NOT(_xlfn.ISFORMULA('#_Sheet1'!G3)),IF(_xlfn.IFS(ISTEXT('#_Sheet1'!G3),FALSE,ISLOGICAL('#_Sheet1'!G3),FALSE,SUBSTITUTE(CELL("format",'#_Sheet1'!G3),"-","")=SUBSTITUTE(CELL("format",Sheet1!G3),"-",""),FALSE,CELL("format",'#_Sheet1'!G3)="G",FALSE,AND(CELL("format",'#_Sheet1'!G3)="F0",CELL("format",Sheet1!G3)="G"),FALSE,TRUE,IFERROR(IF(MATCH(CELL("format",'#_Sheet1'!G3),FormatCodesSFX!$A$4:$A$53,0)>0,TRUE),FALSE),TRUE,TRUE),"FormatMsg","PerfectMsg"),_xlfn.IFS(ISTEXT('#_Sheet1'!G3),FALSE,ISLOGICAL('#_Sheet1'!G3),FALSE,SUBSTITUTE(CELL("format",'#_Sheet1'!G3),"-","")=SUBSTITUTE(CELL("format",Sheet1!G3),"-",""),FALSE,CELL("format",'#_Sheet1'!G3)="G",FALSE,AND(CELL("format",'#_Sheet1'!G3)="F0",CELL("format",Sheet1!G3)="G"),FALSE,TRUE,IFERROR(IF(MATCH(CELL("format",'#_Sheet1'!G3),FormatCodesSFX!$A$4:$A$53,0)>0,TRUE),FALSE),TRUE,TRUE),"FormatMsg",TRUE,"PerfectMsg") | H3: =_xlfn.IFS(ISBLANK(Sheet1!H3),"",IF(NOT(ISNA('#_Sheet1'!H3)),IF(ISNA(Sheet1!H3),TRUE,FALSE),FALSE),"StuNAMsg",IF(AND(ISNA('#_Sheet1'!H3),ISNA(Sheet1!H3)),TRUE,FALSE),"PerfectMsg",IF(NOT(ISERROR('#_Sheet1'!H3)),IF(ISERROR(Sheet1!H3),TRUE,FALSE),FALSE),"StuErrorMsg",IF(TYPE('#_Sheet1'!H3)<>TYPE(Sheet1!H3),TRUE,FALSE),"WrongTypeMsg",IF(ISNUMBER('#_Sheet1'!H3),IF(ABS('#_Sheet1'!H3-Sheet1!H3)>0.00001,TRUE,FALSE),IF('#_Sheet1'!H3<>Sheet1!H3,TRUE,FALSE)),IF(ISNUMBER('#_Sheet1'!H3),IF('#_Sheet1'!H3>Sheet1!H3,"TooLow","TooHigh"),"WrongAnswer"),NOT(_xlfn.ISFORMULA('#_Sheet1'!H3)),IF(_xlfn.IFS(ISTEXT('#_Sheet1'!H3),FALSE,ISLOGICAL('#_Sheet1'!H3),FALSE,SUBSTITUTE(CELL("format",'#_Sheet1'!H3),"-","")=SUBSTITUTE(CELL("format",Sheet1!H3),"-",""),FALSE,CELL("format",'#_Sheet1'!H3)="G",FALSE,AND(CELL("format",'#_Sheet1'!H3)="F0",CELL("format",Sheet1!H3)="G"),FALSE,TRUE,IFERROR(IF(MATCH(CELL("format",'#_Sheet1'!H3),FormatCodesSFX!$A$4:$A$53,0)>0,TRUE),FALSE),TRUE,TRUE),"FormatMsg","PerfectMsg"),_xlfn.IFS(ISTEXT('#_Sheet1'!H3),FALSE,ISLOGICAL('#_Sheet1'!H3),FALSE,SUBSTITUTE(CELL("format",'#_Sheet1'!H3),"-","")=SUBSTITUTE(CELL("format",Sheet1!H3),"-",""),FALSE,CELL("format",'#_Sheet1'!H3)="G",FALSE,AND(CELL("format",'#_Sheet1'!H3)="F0",CELL("format",Sheet1!H3)="G"),FALSE,TRUE,IFERROR(IF(MATCH(CELL("format",'#_Sheet1'!H3),FormatCodesSFX!$A$4:$A$53,0)>0,TRUE),FALSE),TRUE,TRUE),"FormatMsg",TRUE,"PerfectMsg")
A4: =_xlfn.IFS(ISBLANK(Sheet1!A4),"",IF(NOT(ISNA('#_Sheet1'!A4)),IF(ISNA(Sheet1!A4),TRUE,FALSE),FALSE),"StuNAMsg",IF(AND(ISNA('#_Sheet1'!A4),ISNA(Sheet1!A4)),TRUE,FALSE),"PerfectMsg",IF(NOT(ISERROR('#_Sheet1'!A4)),IF(ISERROR(Sheet1!A4),TRUE,FALSE),FALSE),"StuErrorMsg",IF(TYPE('#_Sheet1'!A4)<>TYPE(Sheet1!A4),TRUE,FALSE),"WrongTypeMsg",IF(ISNUMBER('#_Sheet1'!A4),IF(ABS('#_Sheet1'!A4-Sheet1!A4)>0.00001,TRUE,FALSE),IF('#_Sheet1'!A4<>Sheet1!A4,TRUE,FALSE)),IF(ISNUMBER('#_Sheet1'!A4),IF('#_Sheet1'!A4>Sheet1!A4,"TooLow","TooHigh"),"WrongAnswer"),NOT(_xlfn.ISFORMULA('#_Sheet1'!A4)),IF(_xlfn.IFS(ISTEXT('#_Sheet1'!A4),FALSE,ISLOGICAL('#_Sheet1'!A4),FALSE,SUBSTITUTE(CELL("format",'#_Sheet1'!A4),"-","")=SUBSTITUTE(CELL("format",Sheet1!A4),"-",""),FALSE,CELL("format",'#_Sheet1'!A4)="G",FALSE,AND(CELL("format",'#_Sheet1'!A4)="F0",CELL("format",Sheet1!A4)="G"),FALSE,TRUE,IFERROR(IF(MATCH(CELL("format",'#_Sheet1'!A4),FormatCodesSFX!$A$4:$A$53,0)>0,TRUE),FALSE),TRUE,TRUE),"FormatMsg","PerfectMsg"),_xlfn.IFS(ISTEXT('#_Sheet1'!A4),FALSE,ISLOGICAL('#_Sheet1'!A4),FALSE,SUBSTITUTE(CELL("format",'#_Sheet1'!A4),"-","")=SUBSTITUTE(CELL("format",Sheet1!A4),"-",""),FALSE,CELL("format",'#_Sheet1'!A4)="G",FALSE,AND(CELL("format",'#_Sheet1'!A4)="F0",CELL("format",Sheet1!A4)="G"),FALSE,TRUE,IFERROR(IF(MATCH(CELL("format",'#_Sheet1'!A4),FormatCodesSFX!$A$4:$A$53,0)>0,TRUE),FALSE),TRUE,TRUE),"FormatMsg",TRUE,"PerfectMsg") | B4: =_xlfn.IFS(ISBLANK(Sheet1!B4),"",IF(NOT(ISNA('#_Sheet1'!B4)),IF(ISNA(Sheet1!B4),TRUE,FALSE),FALSE),"StuNAMsg",IF(AND(ISNA('#_Sheet1'!B4),ISNA(Sheet1!B4)),TRUE,FALSE),"PerfectMsg",IF(NOT(ISERROR('#_Sheet1'!B4)),IF(ISERROR(Sheet1!B4),TRUE,FALSE),FALSE),"StuErrorMsg",IF(TYPE('#_Sheet1'!B4)<>TYPE(Sheet1!B4),TRUE,FALSE),"WrongTypeMsg",IF(ISNUMBER('#_Sheet1'!B4),IF(ABS('#_Sheet1'!B4-Sheet1!B4)>0.00001,TRUE,FALSE),IF('#_Sheet1'!B4<>Sheet1!B4,TRUE,FALSE)),IF(ISNUMBER('#_Sheet1'!B4),IF('#_Sheet1'!B4>Sheet1!B4,"TooLow","TooHigh"),"WrongAnswer"),NOT(_xlfn.ISFORMULA('#_Sheet1'!B4)),IF(_xlfn.IFS(ISTEXT('#_Sheet1'!B4),FALSE,ISLOGICAL('#_Sheet1'!B4),FALSE,SUBSTITUTE(CELL("format",'#_Sheet1'!B4),"-","")=SUBSTITUTE(CELL("format",Sheet1!B4),"-",""),FALSE,CELL("format",'#_Sheet1'!B4)="G",FALSE,AND(CELL("format",'#_Sheet1'!B4)="F0",CELL("format",Sheet1!B4)="G"),FALSE,TRUE,IFERROR(IF(MATCH(CELL("format",'#_Sheet1'!B4),FormatCodesSFX!$A$4:$A$53,0)>0,TRUE),FALSE),TRUE,TRUE),"FormatMsg","PerfectMsg"),_xlfn.IFS(ISTEXT('#_Sheet1'!B4),FALSE,ISLOGICAL('#_Sheet1'!B4),FALSE,SUBSTITUTE(CELL("format",'#_Sheet1'!B4),"-","")=SUBSTITUTE(CELL("format",Sheet1!B4),"-",""),FALSE,CELL("format",'#_Sheet1'!B4)="G",FALSE,AND(CELL("format",'#_Sheet1'!B4)="F0",CELL("format",Sheet1!B4)="G"),FALSE,TRUE,IFERROR(IF(MATCH(CELL("format",'#_Sheet1'!B4),FormatCodesSFX!$A$4:$A$53,0)>0,TRUE),FALSE),TRUE,TRUE),"FormatMsg",TRUE,"PerfectMsg") | C4: =_xlfn.IFS(ISBLANK(Sheet1!C4),"",IF(NOT(ISNA('#_Sheet1'!C4)),IF(ISNA(Sheet1!C4),TRUE,FALSE),FALSE),"StuNAMsg",IF(AND(ISNA('#_Sheet1'!C4),ISNA(Sheet1!C4)),TRUE,FALSE),"PerfectMsg",IF(NOT(ISERROR('#_Sheet1'!C4)),IF(ISERROR(Sheet1!C4),TRUE,FALSE),FALSE),"StuErrorMsg",IF(TYPE('#_Sheet1'!C4)<>TYPE(Sheet1!C4),TRUE,FALSE),"WrongTypeMsg",IF(ISNUMBER('#_Sheet1'!C4),IF(ABS('#_Sheet1'!C4-Sheet1!C4)>0.00001,TRUE,FALSE),IF('#_Sheet1'!C4<>Sheet1!C4,TRUE,FALSE)),IF(ISNUMBER('#_Sheet1'!C4),IF('#_Sheet1'!C4>Sheet1!C4,"TooLow","TooHigh"),"WrongAnswer"),NOT(_xlfn.ISFORMULA('#_Sheet1'!C4)),IF(_xlfn.IFS(ISTEXT('#_Sheet1'!C4),FALSE,ISLOGICAL('#_Sheet1'!C4),FALSE,SUBSTITUTE(CELL("format",'#_Sheet1'!C4),"-","")=SUBSTITUTE(CELL("format",Sheet1!C4),"-",""),FALSE,CELL("format",'#_Sheet1'!C4)="G",FALSE,AND(CELL("format",'#_Sheet1'!C4)="F0",CELL("format",Sheet1!C4)="G"),FALSE,TRUE,IFERROR(IF(MATCH(CELL("format",'#_Sheet1'!C4),FormatCodesSFX!$A$4:$A$53,0)>0,TRUE),FALSE),TRUE,TRUE),"FormatMsg","PerfectMsg"),_xlfn.IFS(ISTEXT('#_Sheet1'!C4),FALSE,ISLOGICAL('#_Sheet1'!C4),FALSE,SUBSTITUTE(CELL("format",'#_Sheet1'!C4),"-","")=SUBSTITUTE(CELL("format",Sheet1!C4),"-",""),FALSE,CELL("format",'#_Sheet1'!C4)="G",FALSE,AND(CELL("format",'#_Sheet1'!C4)="F0",CELL("format",Sheet1!C4)="G"),FALSE,TRUE,IFERROR(IF(MATCH(CELL("format",'#_Sheet1'!C4),FormatCodesSFX!$A$4:$A$53,0)>0,TRUE),FALSE),TRUE,TRUE),"FormatMsg",TRUE,"PerfectMsg") | D4: =_xlfn.IFS(ISBLANK(Sheet1!D4),"",IF(NOT(ISNA('#_Sheet1'!D4)),IF(ISNA(Sheet1!D4),TRUE,FALSE),FALSE),"StuNAMsg",IF(AND(ISNA('#_Sheet1'!D4),ISNA(Sheet1!D4)),TRUE,FALSE),"PerfectMsg",IF(NOT(ISERROR('#_Sheet1'!D4)),IF(ISERROR(Sheet1!D4),TRUE,FALSE),FALSE),"StuErrorMsg",IF(TYPE('#_Sheet1'!D4)<>TYPE(Sheet1!D4),TRUE,FALSE),"WrongTypeMsg",IF(ISNUMBER('#_Sheet1'!D4),IF(ABS('#_Sheet1'!D4-Sheet1!D4)>0.00001,TRUE,FALSE),IF('#_Sheet1'!D4<>Sheet1!D4,TRUE,FALSE)),IF(ISNUMBER('#_Sheet1'!D4),IF('#_Sheet1'!D4>Sheet1!D4,"TooLow","TooHigh"),"WrongAnswer"),NOT(_xlfn.ISFORMULA('#_Sheet1'!D4)),IF(_xlfn.IFS(ISTEXT('#_Sheet1'!D4),FALSE,ISLOGICAL('#_Sheet1'!D4),FALSE,SUBSTITUTE(CELL("format",'#_Sheet1'!D4),"-","")=SUBSTITUTE(CELL("format",Sheet1!D4),"-",""),FALSE,CELL("format",'#_Sheet1'!D4)="G",FALSE,AND(CELL("format",'#_Sheet1'!D4)="F0",CELL("format",Sheet1!D4)="G"),FALSE,TRUE,IFERROR(IF(MATCH(CELL("format",'#_Sheet1'!D4),FormatCodesSFX!$A$4:$A$53,0)>0,TRUE),FALSE),TRUE,TRUE),"FormatMsg","PerfectMsg"),_xlfn.IFS(ISTEXT('#_Sheet1'!D4),FALSE,ISLOGICAL('#_Sheet1'!D4),FALSE,SUBSTITUTE(CELL("format",'#_Sheet1'!D4),"-","")=SUBSTITUTE(CELL("format",Sheet1!D4),"-",""),FALSE,CELL("format",'#_Sheet1'!D4)="G",FALSE,AND(CELL("format",'#_Sheet1'!D4)="F0",CELL("format",Sheet1!D4)="G"),FALSE,TRUE,IFERROR(IF(MATCH(CELL("format",'#_Sheet1'!D4),FormatCodesSFX!$A$4:$A$53,0)>0,TRUE),FALSE),TRUE,TRUE),"FormatMsg",TRUE,"PerfectMsg") | E4: =_xlfn.IFS(ISBLANK(Sheet1!E4),"",IF(NOT(ISNA('#_Sheet1'!E4)),IF(ISNA(Sheet1!E4),TRUE,FALSE),FALSE),"StuNAMsg",IF(AND(ISNA('#_Sheet1'!E4),ISNA(Sheet1!E4)),TRUE,FALSE),"PerfectMsg",IF(NOT(ISERROR('#_Sheet1'!E4)),IF(ISERROR(Sheet1!E4),TRUE,FALSE),FALSE),"StuErrorMsg",IF(TYPE('#_Sheet1'!E4)<>TYPE(Sheet1!E4),TRUE,FALSE),"WrongTypeMsg",IF(ISNUMBER('#_Sheet1'!E4),IF(ABS('#_Sheet1'!E4-Sheet1!E4)>0.00001,TRUE,FALSE),IF('#_Sheet1'!E4<>Sheet1!E4,TRUE,FALSE)),IF(ISNUMBER('#_Sheet1'!E4),IF('#_Sheet1'!E4>Sheet1!E4,"TooLow","TooHigh"),"WrongAnswer"),NOT(_xlfn.ISFORMULA('#_Sheet1'!E4)),IF(_xlfn.IFS(ISTEXT('#_Sheet1'!E4),FALSE,ISLOGICAL('#_Sheet1'!E4),FALSE,SUBSTITUTE(CELL("format",'#_Sheet1'!E4),"-","")=SUBSTITUTE(CELL("format",Sheet1!E4),"-",""),FALSE,CELL("format",'#_Sheet1'!E4)="G",FALSE,AND(CELL("format",'#_Sheet1'!E4)="F0",CELL("format",Sheet1!E4)="G"),FALSE,TRUE,IFERROR(IF(MATCH(CELL("format",'#_Sheet1'!E4),FormatCodesSFX!$A$4:$A$53,0)>0,TRUE),FALSE),TRUE,TRUE),"FormatMsg","PerfectMsg"),_xlfn.IFS(ISTEXT('#_Sheet1'!E4),FALSE,ISLOGICAL('#_Sheet1'!E4),FALSE,SUBSTITUTE(CELL("format",'#_Sheet1'!E4),"-","")=SUBSTITUTE(CELL("format",Sheet1!E4),"-",""),FALSE,CELL("format",'#_Sheet1'!E4)="G",FALSE,AND(CELL("format",'#_Sheet1'!E4)="F0",CELL("format",Sheet1!E4)="G"),FALSE,TRUE,IFERROR(IF(MATCH(CELL("format",'#_Sheet1'!E4),FormatCodesSFX!$A$4:$A$53,0)>0,TRUE),FALSE),TRUE,TRUE),"FormatMsg",TRUE,"PerfectMsg") | F4: =_xlfn.IFS(ISBLANK(Sheet1!F4),"",IF(NOT(ISNA('#_Sheet1'!F4)),IF(ISNA(Sheet1!F4),TRUE,FALSE),FALSE),"StuNAMsg",IF(AND(ISNA('#_Sheet1'!F4),ISNA(Sheet1!F4)),TRUE,FALSE),"PerfectMsg",IF(NOT(ISERROR('#_Sheet1'!F4)),IF(ISERROR(Sheet1!F4),TRUE,FALSE),FALSE),"StuErrorMsg",IF(TYPE('#_Sheet1'!F4)<>TYPE(Sheet1!F4),TRUE,FALSE),"WrongTypeMsg",IF(ISNUMBER('#_Sheet1'!F4),IF(ABS('#_Sheet1'!F4-Sheet1!F4)>0.00001,TRUE,FALSE),IF('#_Sheet1'!F4<>Sheet1!F4,TRUE,FALSE)),IF(ISNUMBER('#_Sheet1'!F4),IF('#_Sheet1'!F4>Sheet1!F4,"TooLow","TooHigh"),"WrongAnswer"),NOT(_xlfn.ISFORMULA('#_Sheet1'!F4)),IF(_xlfn.IFS(ISTEXT('#_Sheet1'!F4),FALSE,ISLOGICAL('#_Sheet1'!F4),FALSE,SUBSTITUTE(CELL("format",'#_Sheet1'!F4),"-","")=SUBSTITUTE(CELL("format",Sheet1!F4),"-",""),FALSE,CELL("format",'#_Sheet1'!F4)="G",FALSE,AND(CELL("format",'#_Sheet1'!F4)="F0",CELL("format",Sheet1!F4)="G"),FALSE,TRUE,IFERROR(IF(MATCH(CELL("format",'#_Sheet1'!F4),FormatCodesSFX!$A$4:$A$53,0)>0,TRUE),FALSE),TRUE,TRUE),"FormatMsg","PerfectMsg"),_xlfn.IFS(ISTEXT('#_Sheet1'!F4),FALSE,ISLOGICAL('#_Sheet1'!F4),FALSE,SUBSTITUTE(CELL("format",'#_Sheet1'!F4),"-","")=SUBSTITUTE(CELL("format",Sheet1!F4),"-",""),FALSE,CELL("format",'#_Sheet1'!F4)="G",FALSE,AND(CELL("format",'#_Sheet1'!F4)="F0",CELL("format",Sheet1!F4)="G"),FALSE,TRUE,IFERROR(IF(MATCH(CELL("format",'#_Sheet1'!F4),FormatCodesSFX!$A$4:$A$53,0)>0,TRUE),FALSE),TRUE,TRUE),"FormatMsg",TRUE,"PerfectMsg") | G4: =_xlfn.IFS(ISBLANK(Sheet1!G4),"",IF(NOT(ISNA('#_Sheet1'!G4)),IF(ISNA(Sheet1!G4),TRUE,FALSE),FALSE),"StuNAMsg",IF(AND(ISNA('#_Sheet1'!G4),ISNA(Sheet1!G4)),TRUE,FALSE),"PerfectMsg",IF(NOT(ISERROR('#_Sheet1'!G4)),IF(ISERROR(Sheet1!G4),TRUE,FALSE),FALSE),"StuErrorMsg",IF(TYPE('#_Sheet1'!G4)<>TYPE(Sheet1!G4),TRUE,FALSE),"WrongTypeMsg",IF(ISNUMBER('#_Sheet1'!G4),IF(ABS('#_Sheet1'!G4-Sheet1!G4)>0.00001,TRUE,FALSE),IF('#_Sheet1'!G4<>Sheet1!G4,TRUE,FALSE)),IF(ISNUMBER('#_Sheet1'!G4),IF('#_Sheet1'!G4>Sheet1!G4,"TooLow","TooHigh"),"WrongAnswer"),NOT(_xlfn.ISFORMULA('#_Sheet1'!G4)),IF(_xlfn.IFS(ISTEXT('#_Sheet1'!G4),FALSE,ISLOGICAL('#_Sheet1'!G4),FALSE,SUBSTITUTE(CELL("format",'#_Sheet1'!G4),"-","")=SUBSTITUTE(CELL("format",Sheet1!G4),"-",""),FALSE,CELL("format",'#_Sheet1'!G4)="G",FALSE,AND(CELL("format",'#_Sheet1'!G4)="F0",CELL("format",Sheet1!G4)="G"),FALSE,TRUE,IFERROR(IF(MATCH(CELL("format",'#_Sheet1'!G4),FormatCodesSFX!$A$4:$A$53,0)>0,TRUE),FALSE),TRUE,TRUE),"FormatMsg","PerfectMsg"),_xlfn.IFS(ISTEXT('#_Sheet1'!G4),FALSE,ISLOGICAL('#_Sheet1'!G4),FALSE,SUBSTITUTE(CELL("format",'#_Sheet1'!G4),"-","")=SUBSTITUTE(CELL("format",Sheet1!G4),"-",""),FALSE,CELL("format",'#_Sheet1'!G4)="G",FALSE,AND(CELL("format",'#_Sheet1'!G4)="F0",CELL("format",Sheet1!G4)="G"),FALSE,TRUE,IFERROR(IF(MATCH(CELL("format",'#_Sheet1'!G4),FormatCodesSFX!$A$4:$A$53,0)>0,TRUE),FALSE),TRUE,TRUE),"FormatMsg",TRUE,"PerfectMsg") | H4: =_xlfn.IFS(ISBLANK(Sheet1!H4),"",IF(NOT(ISNA('#_Sheet1'!H4)),IF(ISNA(Sheet1!H4),TRUE,FALSE),FALSE),"StuNAMsg",IF(AND(ISNA('#_Sheet1'!H4),ISNA(Sheet1!H4)),TRUE,FALSE),"PerfectMsg",IF(NOT(ISERROR('#_Sheet1'!H4)),IF(ISERROR(Sheet1!H4),TRUE,FALSE),FALSE),"StuErrorMsg",IF(TYPE('#_Sheet1'!H4)<>TYPE(Sheet1!H4),TRUE,FALSE),"WrongTypeMsg",IF(ISNUMBER('#_Sheet1'!H4),IF(ABS('#_Sheet1'!H4-Sheet1!H4)>0.00001,TRUE,FALSE),IF('#_Sheet1'!H4<>Sheet1!H4,TRUE,FALSE)),IF(ISNUMBER('#_Sheet1'!H4),IF('#_Sheet1'!H4>Sheet1!H4,"TooLow","TooHigh"),"WrongAnswer"),NOT(_xlfn.ISFORMULA('#_Sheet1'!H4)),IF(_xlfn.IFS(ISTEXT('#_Sheet1'!H4),FALSE,ISLOGICAL('#_Sheet1'!H4),FALSE,SUBSTITUTE(CELL("format",'#_Sheet1'!H4),"-","")=SUBSTITUTE(CELL("format",Sheet1!H4),"-",""),FALSE,CELL("format",'#_Sheet1'!H4)="G",FALSE,AND(CELL("format",'#_Sheet1'!H4)="F0",CELL("format",Sheet1!H4)="G"),FALSE,TRUE,IFERROR(IF(MATCH(CELL("format",'#_Sheet1'!H4),FormatCodesSFX!$A$4:$A$53,0)>0,TRUE),FALSE),TRUE,TRUE),"FormatMsg","PerfectMsg"),_xlfn.IFS(ISTEXT('#_Sheet1'!H4),FALSE,ISLOGICAL('#_Sheet1'!H4),FALSE,SUBSTITUTE(CELL("format",'#_Sheet1'!H4),"-","")=SUBSTITUTE(CELL("format",Sheet1!H4),"-",""),FALSE,CELL("format",'#_Sheet1'!H4)="G",FALSE,AND(CELL("format",'#_Sheet1'!H4)="F0",CELL("format",Sheet1!H4)="G"),FALSE,TRUE,IFERROR(IF(MATCH(CELL("format",'#_Sheet1'!H4),FormatCodesSFX!$A$4:$A$53,0)>0,TRUE),FALSE),TRUE,TRUE),"FormatMsg",TRUE,"PerfectMsg")
A5: =_xlfn.IFS(ISBLANK(Sheet1!A5),"",IF(NOT(ISNA('#_Sheet1'!A5)),IF(ISNA(Sheet1!A5),TRUE,FALSE),FALSE),"StuNAMsg",IF(AND(ISNA('#_Sheet1'!A5),ISNA(Sheet1!A5)),TRUE,FALSE),"PerfectMsg",IF(NOT(ISERROR('#_Sheet1'!A5)),IF(ISERROR(Sheet1!A5),TRUE,FALSE),FALSE),"StuErrorMsg",IF(TYPE('#_Sheet1'!A5)<>TYPE(Sheet1!A5),TRUE,FALSE),"WrongTypeMsg",IF(ISNUMBER('#_Sheet1'!A5),IF(ABS('#_Sheet1'!A5-Sheet1!A5)>0.00001,TRUE,FALSE),IF('#_Sheet1'!A5<>Sheet1!A5,TRUE,FALSE)),IF(ISNUMBER('#_Sheet1'!A5),IF('#_Sheet1'!A5>Sheet1!A5,"TooLow","TooHigh"),"WrongAnswer"),NOT(_xlfn.ISFORMULA('#_Sheet1'!A5)),IF(_xlfn.IFS(ISTEXT('#_Sheet1'!A5),FALSE,ISLOGICAL('#_Sheet1'!A5),FALSE,SUBSTITUTE(CELL("format",'#_Sheet1'!A5),"-","")=SUBSTITUTE(CELL("format",Sheet1!A5),"-",""),FALSE,CELL("format",'#_Sheet1'!A5)="G",FALSE,AND(CELL("format",'#_Sheet1'!A5)="F0",CELL("format",Sheet1!A5)="G"),FALSE,TRUE,IFERROR(IF(MATCH(CELL("format",'#_Sheet1'!A5),FormatCodesSFX!$A$4:$A$53,0)>0,TRUE),FALSE),TRUE,TRUE),"FormatMsg","PerfectMsg"),_xlfn.IFS(ISTEXT('#_Sheet1'!A5),FALSE,ISLOGICAL('#_Sheet1'!A5),FALSE,SUBSTITUTE(CELL("format",'#_Sheet1'!A5),"-","")=SUBSTITUTE(CELL("format",Sheet1!A5),"-",""),FALSE,CELL("format",'#_Sheet1'!A5)="G",FALSE,AND(CELL("format",'#_Sheet1'!A5)="F0",CELL("format",Sheet1!A5)="G"),FALSE,TRUE,IFERROR(IF(MATCH(CELL("format",'#_Sheet1'!A5),FormatCodesSFX!$A$4:$A$53,0)>0,TRUE),FALSE),TRUE,TRUE),"FormatMsg",TRUE,"PerfectMsg") | B5: =_xlfn.IFS(ISBLANK(Sheet1!B5),"",IF(NOT(ISNA('#_Sheet1'!B5)),IF(ISNA(Sheet1!B5),TRUE,FALSE),FALSE),"StuNAMsg",IF(AND(ISNA('#_Sheet1'!B5),ISNA(Sheet1!B5)),TRUE,FALSE),"PerfectMsg",IF(NOT(ISERROR('#_Sheet1'!B5)),IF(ISERROR(Sheet1!B5),TRUE,FALSE),FALSE),"StuErrorMsg",IF(TYPE('#_Sheet1'!B5)<>TYPE(Sheet1!B5),TRUE,FALSE),"WrongTypeMsg",IF(ISNUMBER('#_Sheet1'!B5),IF(ABS('#_Sheet1'!B5-Sheet1!B5)>0.00001,TRUE,FALSE),IF('#_Sheet1'!B5<>Sheet1!B5,TRUE,FALSE)),IF(ISNUMBER('#_Sheet1'!B5),IF('#_Sheet1'!B5>Sheet1!B5,"TooLow","TooHigh"),"WrongAnswer"),NOT(_xlfn.ISFORMULA('#_Sheet1'!B5)),IF(_xlfn.IFS(ISTEXT('#_Sheet1'!B5),FALSE,ISLOGICAL('#_Sheet1'!B5),FALSE,SUBSTITUTE(CELL("format",'#_Sheet1'!B5),"-","")=SUBSTITUTE(CELL("format",Sheet1!B5),"-",""),FALSE,CELL("format",'#_Sheet1'!B5)="G",FALSE,AND(CELL("format",'#_Sheet1'!B5)="F0",CELL("format",Sheet1!B5)="G"),FALSE,TRUE,IFERROR(IF(MATCH(CELL("format",'#_Sheet1'!B5),FormatCodesSFX!$A$4:$A$53,0)>0,TRUE),FALSE),TRUE,TRUE),"FormatMsg","PerfectMsg"),_xlfn.IFS(ISTEXT('#_Sheet1'!B5),FALSE,ISLOGICAL('#_Sheet1'!B5),FALSE,SUBSTITUTE(CELL("format",'#_Sheet1'!B5),"-","")=SUBSTITUTE(CELL("format",Sheet1!B5),"-",""),FALSE,CELL("format",'#_Sheet1'!B5)="G",FALSE,AND(CELL("format",'#_Sheet1'!B5)="F0",CELL("format",Sheet1!B5)="G"),FALSE,TRUE,IFERROR(IF(MATCH(CELL("format",'#_Sheet1'!B5),FormatCodesSFX!$A$4:$A$53,0)>0,TRUE),FALSE),TRUE,TRUE),"FormatMsg",TRUE,"PerfectMsg") | C5: =_xlfn.IFS(ISBLANK(Sheet1!C5),"",IF(NOT(ISNA('#_Sheet1'!C5)),IF(ISNA(Sheet1!C5),TRUE,FALSE),FALSE),"StuNAMsg",IF(AND(ISNA('#_Sheet1'!C5),ISNA(Sheet1!C5)),TRUE,FALSE),"PerfectMsg",IF(NOT(ISERROR('#_Sheet1'!C5)),IF(ISERROR(Sheet1!C5),TRUE,FALSE),FALSE),"StuErrorMsg",IF(TYPE('#_Sheet1'!C5)<>TYPE(Sheet1!C5),TRUE,FALSE),"WrongTypeMsg",IF(ISNUMBER('#_Sheet1'!C5),IF(ABS('#_Sheet1'!C5-Sheet1!C5)>0.00001,TRUE,FALSE),IF('#_Sheet1'!C5<>Sheet1!C5,TRUE,FALSE)),IF(ISNUMBER('#_Sheet1'!C5),IF('#_Sheet1'!C5>Sheet1!C5,"TooLow","TooHigh"),"WrongAnswer"),NOT(_xlfn.ISFORMULA('#_Sheet1'!C5)),IF(_xlfn.IFS(ISTEXT('#_Sheet1'!C5),FALSE,ISLOGICAL('#_Sheet1'!C5),FALSE,SUBSTITUTE(CELL("format",'#_Sheet1'!C5),"-","")=SUBSTITUTE(CELL("format",Sheet1!C5),"-",""),FALSE,CELL("format",'#_Sheet1'!C5)="G",FALSE,AND(CELL("format",'#_Sheet1'!C5)="F0",CELL("format",Sheet1!C5)="G"),FALSE,TRUE,IFERROR(IF(MATCH(CELL("format",'#_Sheet1'!C5),FormatCodesSFX!$A$4:$A$53,0)>0,TRUE),FALSE),TRUE,TRUE),"FormatMsg","PerfectMsg"),_xlfn.IFS(ISTEXT('#_Sheet1'!C5),FALSE,ISLOGICAL('#_Sheet1'!C5),FALSE,SUBSTITUTE(CELL("format",'#_Sheet1'!C5),"-","")=SUBSTITUTE(CELL("format",Sheet1!C5),"-",""),FALSE,CELL("format",'#_Sheet1'!C5)="G",FALSE,AND(CELL("format",'#_Sheet1'!C5)="F0",CELL("format",Sheet1!C5)="G"),FALSE,TRUE,IFERROR(IF(MATCH(CELL("format",'#_Sheet1'!C5),FormatCodesSFX!$A$4:$A$53,0)>0,TRUE),FALSE),TRUE,TRUE),"FormatMsg",TRUE,"PerfectMsg") | D5: =_xlfn.IFS(ISBLANK(Sheet1!D5),"",IF(NOT(ISNA('#_Sheet1'!D5)),IF(ISNA(Sheet1!D5),TRUE,FALSE),FALSE),"StuNAMsg",IF(AND(ISNA('#_Sheet1'!D5),ISNA(Sheet1!D5)),TRUE,FALSE),"PerfectMsg",IF(NOT(ISERROR('#_Sheet1'!D5)),IF(ISERROR(Sheet1!D5),TRUE,FALSE),FALSE),"StuErrorMsg",IF(TYPE('#_Sheet1'!D5)<>TYPE(Sheet1!D5),TRUE,FALSE),"WrongTypeMsg",IF(ISNUMBER('#_Sheet1'!D5),IF(ABS('#_Sheet1'!D5-Sheet1!D5)>0.00001,TRUE,FALSE),IF('#_Sheet1'!D5<>Sheet1!D5,TRUE,FALSE)),IF(ISNUMBER('#_Sheet1'!D5),IF('#_Sheet1'!D5>Sheet1!D5,"TooLow","TooHigh"),"WrongAnswer"),NOT(_xlfn.ISFORMULA('#_Sheet1'!D5)),IF(_xlfn.IFS(ISTEXT('#_Sheet1'!D5),FALSE,ISLOGICAL('#_Sheet1'!D5),FALSE,SUBSTITUTE(CELL("format",'#_Sheet1'!D5),"-","")=SUBSTITUTE(CELL("format",Sheet1!D5),"-",""),FALSE,CELL("format",'#_Sheet1'!D5)="G",FALSE,AND(CELL("format",'#_Sheet1'!D5)="F0",CELL("format",Sheet1!D5)="G"),FALSE,TRUE,IFERROR(IF(MATCH(CELL("format",'#_Sheet1'!D5),FormatCodesSFX!$A$4:$A$53,0)>0,TRUE),FALSE),TRUE,TRUE),"FormatMsg","PerfectMsg"),_xlfn.IFS(ISTEXT('#_Sheet1'!D5),FALSE,ISLOGICAL('#_Sheet1'!D5),FALSE,SUBSTITUTE(CELL("format",'#_Sheet1'!D5),"-","")=SUBSTITUTE(CELL("format",Sheet1!D5),"-",""),FALSE,CELL("format",'#_Sheet1'!D5)="G",FALSE,AND(CELL("format",'#_Sheet1'!D5)="F0",CELL("format",Sheet1!D5)="G"),FALSE,TRUE,IFERROR(IF(MATCH(CELL("format",'#_Sheet1'!D5),FormatCodesSFX!$A$4:$A$53,0)>0,TRUE),FALSE),TRUE,TRUE),"FormatMsg",TRUE,"PerfectMsg") | E5: =_xlfn.IFS(ISBLANK(Sheet1!E5),"",IF(NOT(ISNA('#_Sheet1'!E5)),IF(ISNA(Sheet1!E5),TRUE,FALSE),FALSE),"StuNAMsg",IF(AND(ISNA('#_Sheet1'!E5),ISNA(Sheet1!E5)),TRUE,FALSE),"PerfectMsg",IF(NOT(ISERROR('#_Sheet1'!E5)),IF(ISERROR(Sheet1!E5),TRUE,FALSE),FALSE),"StuErrorMsg",IF(TYPE('#_Sheet1'!E5)<>TYPE(Sheet1!E5),TRUE,FALSE),"WrongTypeMsg",IF(ISNUMBER('#_Sheet1'!E5),IF(ABS('#_Sheet1'!E5-Sheet1!E5)>0.00001,TRUE,FALSE),IF('#_Sheet1'!E5<>Sheet1!E5,TRUE,FALSE)),IF(ISNUMBER('#_Sheet1'!E5),IF('#_Sheet1'!E5>Sheet1!E5,"TooLow","TooHigh"),"WrongAnswer"),NOT(_xlfn.ISFORMULA('#_Sheet1'!E5)),IF(_xlfn.IFS(ISTEXT('#_Sheet1'!E5),FALSE,ISLOGICAL('#_Sheet1'!E5),FALSE,SUBSTITUTE(CELL("format",'#_Sheet1'!E5),"-","")=SUBSTITUTE(CELL("format",Sheet1!E5),"-",""),FALSE,CELL("format",'#_Sheet1'!E5)="G",FALSE,AND(CELL("format",'#_Sheet1'!E5)="F0",CELL("format",Sheet1!E5)="G"),FALSE,TRUE,IFERROR(IF(MATCH(CELL("format",'#_Sheet1'!E5),FormatCodesSFX!$A$4:$A$53,0)>0,TRUE),FALSE),TRUE,TRUE),"FormatMsg","PerfectMsg"),_xlfn.IFS(ISTEXT('#_Sheet1'!E5),FALSE,ISLOGICAL('#_Sheet1'!E5),FALSE,SUBSTITUTE(CELL("format",'#_Sheet1'!E5),"-","")=SUBSTITUTE(CELL("format",Sheet1!E5),"-",""),FALSE,CELL("format",'#_Sheet1'!E5)="G",FALSE,AND(CELL("format",'#_Sheet1'!E5)="F0",CELL("format",Sheet1!E5)="G"),FALSE,TRUE,IFERROR(IF(MATCH(CELL("format",'#_Sheet1'!E5),FormatCodesSFX!$A$4:$A$53,0)>0,TRUE),FALSE),TRUE,TRUE),"FormatMsg",TRUE,"PerfectMsg") | F5: =_xlfn.IFS(ISBLANK(Sheet1!F5),"",IF(NOT(ISNA('#_Sheet1'!F5)),IF(ISNA(Sheet1!F5),TRUE,FALSE),FALSE),"StuNAMsg",IF(AND(ISNA('#_Sheet1'!F5),ISNA(Sheet1!F5)),TRUE,FALSE),"PerfectMsg",IF(NOT(ISERROR('#_Sheet1'!F5)),IF(ISERROR(Sheet1!F5),TRUE,FALSE),FALSE),"StuErrorMsg",IF(TYPE('#_Sheet1'!F5)<>TYPE(Sheet1!F5),TRUE,FALSE),"WrongTypeMsg",IF(ISNUMBER('#_Sheet1'!F5),IF(ABS('#_Sheet1'!F5-Sheet1!F5)>0.00001,TRUE,FALSE),IF('#_Sheet1'!F5<>Sheet1!F5,TRUE,FALSE)),IF(ISNUMBER('#_Sheet1'!F5),IF('#_Sheet1'!F5>Sheet1!F5,"TooLow","TooHigh"),"WrongAnswer"),NOT(_xlfn.ISFORMULA('#_Sheet1'!F5)),IF(_xlfn.IFS(ISTEXT('#_Sheet1'!F5),FALSE,ISLOGICAL('#_Sheet1'!F5),FALSE,SUBSTITUTE(CELL("format",'#_Sheet1'!F5),"-","")=SUBSTITUTE(CELL("format",Sheet1!F5),"-",""),FALSE,CELL("format",'#_Sheet1'!F5)="G",FALSE,AND(CELL("format",'#_Sheet1'!F5)="F0",CELL("format",Sheet1!F5)="G"),FALSE,TRUE,IFERROR(IF(MATCH(CELL("format",'#_Sheet1'!F5),FormatCodesSFX!$A$4:$A$53,0)>0,TRUE),FALSE),TRUE,TRUE),"FormatMsg","PerfectMsg"),_xlfn.IFS(ISTEXT('#_Sheet1'!F5),FALSE,ISLOGICAL('#_Sheet1'!F5),FALSE,SUBSTITUTE(CELL("format",'#_Sheet1'!F5),"-","")=SUBSTITUTE(CELL("format",Sheet1!F5),"-",""),FALSE,CELL("format",'#_Sheet1'!F5)="G",FALSE,AND(CELL("format",'#_Sheet1'!F5)="F0",CELL("format",Sheet1!F5)="G"),FALSE,TRUE,IFERROR(IF(MATCH(CELL("format",'#_Sheet1'!F5),FormatCodesSFX!$A$4:$A$53,0)>0,TRUE),FALSE),TRUE,TRUE),"FormatMsg",TRUE,"PerfectMsg") | G5: =_xlfn.IFS(ISBLANK(Sheet1!G5),"",IF(NOT(ISNA('#_Sheet1'!G5)),IF(ISNA(Sheet1!G5),TRUE,FALSE),FALSE),"StuNAMsg",IF(AND(ISNA('#_Sheet1'!G5),ISNA(Sheet1!G5)),TRUE,FALSE),"PerfectMsg",IF(NOT(ISERROR('#_Sheet1'!G5)),IF(ISERROR(Sheet1!G5),TRUE,FALSE),FALSE),"StuErrorMsg",IF(TYPE('#_Sheet1'!G5)<>TYPE(Sheet1!G5),TRUE,FALSE),"WrongTypeMsg",IF(ISNUMBER('#_Sheet1'!G5),IF(ABS('#_Sheet1'!G5-Sheet1!G5)>0.00001,TRUE,FALSE),IF('#_Sheet1'!G5<>Sheet1!G5,TRUE,FALSE)),IF(ISNUMBER('#_Sheet1'!G5),IF('#_Sheet1'!G5>Sheet1!G5,"TooLow","TooHigh"),"WrongAnswer"),NOT(_xlfn.ISFORMULA('#_Sheet1'!G5)),IF(_xlfn.IFS(ISTEXT('#_Sheet1'!G5),FALSE,ISLOGICAL('#_Sheet1'!G5),FALSE,SUBSTITUTE(CELL("format",'#_Sheet1'!G5),"-","")=SUBSTITUTE(CELL("format",Sheet1!G5),"-",""),FALSE,CELL("format",'#_Sheet1'!G5)="G",FALSE,AND(CELL("format",'#_Sheet1'!G5)="F0",CELL("format",Sheet1!G5)="G"),FALSE,TRUE,IFERROR(IF(MATCH(CELL("format",'#_Sheet1'!G5),FormatCodesSFX!$A$4:$A$53,0)>0,TRUE),FALSE),TRUE,TRUE),"FormatMsg","PerfectMsg"),_xlfn.IFS(ISTEXT('#_Sheet1'!G5),FALSE,ISLOGICAL('#_Sheet1'!G5),FALSE,SUBSTITUTE(CELL("format",'#_Sheet1'!G5),"-","")=SUBSTITUTE(CELL("format",Sheet1!G5),"-",""),FALSE,CELL("format",'#_Sheet1'!G5)="G",FALSE,AND(CELL("format",'#_Sheet1'!G5)="F0",CELL("format",Sheet1!G5)="G"),FALSE,TRUE,IFERROR(IF(MATCH(CELL("format",'#_Sheet1'!G5),FormatCodesSFX!$A$4:$A$53,0)>0,TRUE),FALSE),TRUE,TRUE),"FormatMsg",TRUE,"PerfectMsg") | H5: =_xlfn.IFS(ISBLANK(Sheet1!H5),"",IF(NOT(ISNA('#_Sheet1'!H5)),IF(ISNA(Sheet1!H5),TRUE,FALSE),FALSE),"StuNAMsg",IF(AND(ISNA('#_Sheet1'!H5),ISNA(Sheet1!H5)),TRUE,FALSE),"PerfectMsg",IF(NOT(ISERROR('#_Sheet1'!H5)),IF(ISERROR(Sheet1!H5),TRUE,FALSE),FALSE),"StuErrorMsg",IF(TYPE('#_Sheet1'!H5)<>TYPE(Sheet1!H5),TRUE,FALSE),"WrongTypeMsg",IF(ISNUMBER('#_Sheet1'!H5),IF(ABS('#_Sheet1'!H5-Sheet1!H5)>0.00001,TRUE,FALSE),IF('#_Sheet1'!H5<>Sheet1!H5,TRUE,FALSE)),IF(ISNUMBER('#_Sheet1'!H5),IF('#_Sheet1'!H5>Sheet1!H5,"TooLow","TooHigh"),"WrongAnswer"),NOT(_xlfn.ISFORMULA('#_Sheet1'!H5)),IF(_xlfn.IFS(ISTEXT('#_Sheet1'!H5),FALSE,ISLOGICAL('#_Sheet1'!H5),FALSE,SUBSTITUTE(CELL("format",'#_Sheet1'!H5),"-","")=SUBSTITUTE(CELL("format",Sheet1!H5),"-",""),FALSE,CELL("format",'#_Sheet1'!H5)="G",FALSE,AND(CELL("format",'#_Sheet1'!H5)="F0",CELL("format",Sheet1!H5)="G"),FALSE,TRUE,IFERROR(IF(MATCH(CELL("format",'#_Sheet1'!H5),FormatCodesSFX!$A$4:$A$53,0)>0,TRUE),FALSE),TRUE,TRUE),"FormatMsg","PerfectMsg"),_xlfn.IFS(ISTEXT('#_Sheet1'!H5),FALSE,ISLOGICAL('#_Sheet1'!H5),FALSE,SUBSTITUTE(CELL("format",'#_Sheet1'!H5),"-","")=SUBSTITUTE(CELL("format",Sheet1!H5),"-",""),FALSE,CELL("format",'#_Sheet1'!H5)="G",FALSE,AND(CELL("format",'#_Sheet1'!H5)="F0",CELL("format",Sheet1!H5)="G"),FALSE,TRUE,IFERROR(IF(MATCH(CELL("format",'#_Sheet1'!H5),FormatCodesSFX!$A$4:$A$53,0)>0,TRUE),FALSE),TRUE,TRUE),"FormatMsg",TRUE,"PerfectMsg")
A6: =_xlfn.IFS(ISBLANK(Sheet1!A6),"",IF(NOT(ISNA('#_Sheet1'!A6)),IF(ISNA(Sheet1!A6),TRUE,FALSE),FALSE),"StuNAMsg",IF(AND(ISNA('#_Sheet1'!A6),ISNA(Sheet1!A6)),TRUE,FALSE),"PerfectMsg",IF(NOT(ISERROR('#_Sheet1'!A6)),IF(ISERROR(Sheet1!A6),TRUE,FALSE),FALSE),"StuErrorMsg",IF(TYPE('#_Sheet1'!A6)<>TYPE(Sheet1!A6),TRUE,FALSE),"WrongTypeMsg",IF(ISNUMBER('#_Sheet1'!A6),IF(ABS('#_Sheet1'!A6-Sheet1!A6)>0.00001,TRUE,FALSE),IF('#_Sheet1'!A6<>Sheet1!A6,TRUE,FALSE)),IF(ISNUMBER('#_Sheet1'!A6),IF('#_Sheet1'!A6>Sheet1!A6,"TooLow","TooHigh"),"WrongAnswer"),NOT(_xlfn.ISFORMULA('#_Sheet1'!A6)),IF(_xlfn.IFS(ISTEXT('#_Sheet1'!A6),FALSE,ISLOGICAL('#_Sheet1'!A6),FALSE,SUBSTITUTE(CELL("format",'#_Sheet1'!A6),"-","")=SUBSTITUTE(CELL("format",Sheet1!A6),"-",""),FALSE,CELL("format",'#_Sheet1'!A6)="G",FALSE,AND(CELL("format",'#_Sheet1'!A6)="F0",CELL("format",Sheet1!A6)="G"),FALSE,TRUE,IFERROR(IF(MATCH(CELL("format",'#_Sheet1'!A6),FormatCodesSFX!$A$4:$A$53,0)>0,TRUE),FALSE),TRUE,TRUE),"FormatMsg","PerfectMsg"),_xlfn.IFS(ISTEXT('#_Sheet1'!A6),FALSE,ISLOGICAL('#_Sheet1'!A6),FALSE,SUBSTITUTE(CELL("format",'#_Sheet1'!A6),"-","")=SUBSTITUTE(CELL("format",Sheet1!A6),"-",""),FALSE,CELL("format",'#_Sheet1'!A6)="G",FALSE,AND(CELL("format",'#_Sheet1'!A6)="F0",CELL("format",Sheet1!A6)="G"),FALSE,TRUE,IFERROR(IF(MATCH(CELL("format",'#_Sheet1'!A6),FormatCodesSFX!$A$4:$A$53,0)>0,TRUE),FALSE),TRUE,TRUE),"FormatMsg",TRUE,"PerfectMsg") | B6: =_xlfn.IFS(ISBLANK(Sheet1!B6),"",IF(NOT(ISNA('#_Sheet1'!B6)),IF(ISNA(Sheet1!B6),TRUE,FALSE),FALSE),"StuNAMsg",IF(AND(ISNA('#_Sheet1'!B6),ISNA(Sheet1!B6)),TRUE,FALSE),"PerfectMsg",IF(NOT(ISERROR('#_Sheet1'!B6)),IF(ISERROR(Sheet1!B6),TRUE,FALSE),FALSE),"StuErrorMsg",IF(TYPE('#_Sheet1'!B6)<>TYPE(Sheet1!B6),TRUE,FALSE),"WrongTypeMsg",IF(ISNUMBER('#_Sheet1'!B6),IF(ABS('#_Sheet1'!B6-Sheet1!B6)>0.00001,TRUE,FALSE),IF('#_Sheet1'!B6<>Sheet1!B6,TRUE,FALSE)),IF(ISNUMBER('#_Sheet1'!B6),IF('#_Sheet1'!B6>Sheet1!B6,"TooLow","TooHigh"),"WrongAnswer"),NOT(_xlfn.ISFORMULA('#_Sheet1'!B6)),IF(_xlfn.IFS(ISTEXT('#_Sheet1'!B6),FALSE,ISLOGICAL('#_Sheet1'!B6),FALSE,SUBSTITUTE(CELL("format",'#_Sheet1'!B6),"-","")=SUBSTITUTE(CELL("format",Sheet1!B6),"-",""),FALSE,CELL("format",'#_Sheet1'!B6)="G",FALSE,AND(CELL("format",'#_Sheet1'!B6)="F0",CELL("format",Sheet1!B6)="G"),FALSE,TRUE,IFERROR(IF(MATCH(CELL("format",'#_Sheet1'!B6),FormatCodesSFX!$A$4:$A$53,0)>0,TRUE),FALSE),TRUE,TRUE),"FormatMsg","PerfectMsg"),_xlfn.IFS(ISTEXT('#_Sheet1'!B6),FALSE,ISLOGICAL('#_Sheet1'!B6),FALSE,SUBSTITUTE(CELL("format",'#_Sheet1'!B6),"-","")=SUBSTITUTE(CELL("format",Sheet1!B6),"-",""),FALSE,CELL("format",'#_Sheet1'!B6)="G",FALSE,AND(CELL("format",'#_Sheet1'!B6)="F0",CELL("format",Sheet1!B6)="G"),FALSE,TRUE,IFERROR(IF(MATCH(CELL("format",'#_Sheet1'!B6),FormatCodesSFX!$A$4:$A$53,0)>0,TRUE),FALSE),TRUE,TRUE),"FormatMsg",TRUE,"PerfectMsg") | C6: =_xlfn.IFS(ISBLANK(Sheet1!C6),"",IF(NOT(ISNA('#_Sheet1'!C6)),IF(ISNA(Sheet1!C6),TRUE,FALSE),FALSE),"StuNAMsg",IF(AND(ISNA('#_Sheet1'!C6),ISNA(Sheet1!C6)),TRUE,FALSE),"PerfectMsg",IF(NOT(ISERROR('#_Sheet1'!C6)),IF(ISERROR(Sheet1!C6),TRUE,FALSE),FALSE),"StuErrorMsg",IF(TYPE('#_Sheet1'!C6)<>TYPE(Sheet1!C6),TRUE,FALSE),"WrongTypeMsg",IF(ISNUMBER('#_Sheet1'!C6),IF(ABS('#_Sheet1'!C6-Sheet1!C6)>0.00001,TRUE,FALSE),IF('#_Sheet1'!C6<>Sheet1!C6,TRUE,FALSE)),IF(ISNUMBER('#_Sheet1'!C6),IF('#_Sheet1'!C6>Sheet1!C6,"TooLow","TooHigh"),"WrongAnswer"),NOT(_xlfn.ISFORMULA('#_Sheet1'!C6)),IF(_xlfn.IFS(ISTEXT('#_Sheet1'!C6),FALSE,ISLOGICAL('#_Sheet1'!C6),FALSE,SUBSTITUTE(CELL("format",'#_Sheet1'!C6),"-","")=SUBSTITUTE(CELL("format",Sheet1!C6),"-",""),FALSE,CELL("format",'#_Sheet1'!C6)="G",FALSE,AND(CELL("format",'#_Sheet1'!C6)="F0",CELL("format",Sheet1!C6)="G"),FALSE,TRUE,IFERROR(IF(MATCH(CELL("format",'#_Sheet1'!C6),FormatCodesSFX!$A$4:$A$53,0)>0,TRUE),FALSE),TRUE,TRUE),"FormatMsg","PerfectMsg"),_xlfn.IFS(ISTEXT('#_Sheet1'!C6),FALSE,ISLOGICAL('#_Sheet1'!C6),FALSE,SUBSTITUTE(CELL("format",'#_Sheet1'!C6),"-","")=SUBSTITUTE(CELL("format",Sheet1!C6),"-",""),FALSE,CELL("format",'#_Sheet1'!C6)="G",FALSE,AND(CELL("format",'#_Sheet1'!C6)="F0",CELL("format",Sheet1!C6)="G"),FALSE,TRUE,IFERROR(IF(MATCH(CELL("format",'#_Sheet1'!C6),FormatCodesSFX!$A$4:$A$53,0)>0,TRUE),FALSE),TRUE,TRUE),"FormatMsg",TRUE,"PerfectMsg") | D6: =_xlfn.IFS(ISBLANK(Sheet1!D6),"",IF(NOT(ISNA('#_Sheet1'!D6)),IF(ISNA(Sheet1!D6),TRUE,FALSE),FALSE),"StuNAMsg",IF(AND(ISNA('#_Sheet1'!D6),ISNA(Sheet1!D6)),TRUE,FALSE),"PerfectMsg",IF(NOT(ISERROR('#_Sheet1'!D6)),IF(ISERROR(Sheet1!D6),TRUE,FALSE),FALSE),"StuErrorMsg",IF(TYPE('#_Sheet1'!D6)<>TYPE(Sheet1!D6),TRUE,FALSE),"WrongTypeMsg",IF(ISNUMBER('#_Sheet1'!D6),IF(ABS('#_Sheet1'!D6-Sheet1!D6)>0.00001,TRUE,FALSE),IF('#_Sheet1'!D6<>Sheet1!D6,TRUE,FALSE)),IF(ISNUMBER('#_Sheet1'!D6),IF('#_Sheet1'!D6>Sheet1!D6,"TooLow","TooHigh"),"WrongAnswer"),NOT(_xlfn.ISFORMULA('#_Sheet1'!D6)),IF(_xlfn.IFS(ISTEXT('#_Sheet1'!D6),FALSE,ISLOGICAL('#_Sheet1'!D6),FALSE,SUBSTITUTE(CELL("format",'#_Sheet1'!D6),"-","")=SUBSTITUTE(CELL("format",Sheet1!D6),"-",""),FALSE,CELL("format",'#_Sheet1'!D6)="G",FALSE,AND(CELL("format",'#_Sheet1'!D6)="F0",CELL("format",Sheet1!D6)="G"),FALSE,TRUE,IFERROR(IF(MATCH(CELL("format",'#_Sheet1'!D6),FormatCodesSFX!$A$4:$A$53,0)>0,TRUE),FALSE),TRUE,TRUE),"FormatMsg","PerfectMsg"),_xlfn.IFS(ISTEXT('#_Sheet1'!D6),FALSE,ISLOGICAL('#_Sheet1'!D6),FALSE,SUBSTITUTE(CELL("format",'#_Sheet1'!D6),"-","")=SUBSTITUTE(CELL("format",Sheet1!D6),"-",""),FALSE,CELL("format",'#_Sheet1'!D6)="G",FALSE,AND(CELL("format",'#_Sheet1'!D6)="F0",CELL("format",Sheet1!D6)="G"),FALSE,TRUE,IFERROR(IF(MATCH(CELL("format",'#_Sheet1'!D6),FormatCodesSFX!$A$4:$A$53,0)>0,TRUE),FALSE),TRUE,TRUE),"FormatMsg",TRUE,"PerfectMsg") | E6: =_xlfn.IFS(ISBLANK(Sheet1!E6),"",IF(NOT(ISNA('#_Sheet1'!E6)),IF(ISNA(Sheet1!E6),TRUE,FALSE),FALSE),"StuNAMsg",IF(AND(ISNA('#_Sheet1'!E6),ISNA(Sheet1!E6)),TRUE,FALSE),"PerfectMsg",IF(NOT(ISERROR('#_Sheet1'!E6)),IF(ISERROR(Sheet1!E6),TRUE,FALSE),FALSE),"StuErrorMsg",IF(TYPE('#_Sheet1'!E6)<>TYPE(Sheet1!E6),TRUE,FALSE),"WrongTypeMsg",IF(ISNUMBER('#_Sheet1'!E6),IF(ABS('#_Sheet1'!E6-Sheet1!E6)>0.00001,TRUE,FALSE),IF('#_Sheet1'!E6<>Sheet1!E6,TRUE,FALSE)),IF(ISNUMBER('#_Sheet1'!E6),IF('#_Sheet1'!E6>Sheet1!E6,"TooLow","TooHigh"),"WrongAnswer"),NOT(_xlfn.ISFORMULA('#_Sheet1'!E6)),IF(_xlfn.IFS(ISTEXT('#_Sheet1'!E6),FALSE,ISLOGICAL('#_Sheet1'!E6),FALSE,SUBSTITUTE(CELL("format",'#_Sheet1'!E6),"-","")=SUBSTITUTE(CELL("format",Sheet1!E6),"-",""),FALSE,CELL("format",'#_Sheet1'!E6)="G",FALSE,AND(CELL("format",'#_Sheet1'!E6)="F0",CELL("format",Sheet1!E6)="G"),FALSE,TRUE,IFERROR(IF(MATCH(CELL("format",'#_Sheet1'!E6),FormatCodesSFX!$A$4:$A$53,0)>0,TRUE),FALSE),TRUE,TRUE),"FormatMsg","PerfectMsg"),_xlfn.IFS(ISTEXT('#_Sheet1'!E6),FALSE,ISLOGICAL('#_Sheet1'!E6),FALSE,SUBSTITUTE(CELL("format",'#_Sheet1'!E6),"-","")=SUBSTITUTE(CELL("format",Sheet1!E6),"-",""),FALSE,CELL("format",'#_Sheet1'!E6)="G",FALSE,AND(CELL("format",'#_Sheet1'!E6)="F0",CELL("format",Sheet1!E6)="G"),FALSE,TRUE,IFERROR(IF(MATCH(CELL("format",'#_Sheet1'!E6),FormatCodesSFX!$A$4:$A$53,0)>0,TRUE),FALSE),TRUE,TRUE),"FormatMsg",TRUE,"PerfectMsg") | F6: =_xlfn.IFS(ISBLANK(Sheet1!F6),"",IF(NOT(ISNA('#_Sheet1'!F6)),IF(ISNA(Sheet1!F6),TRUE,FALSE),FALSE),"StuNAMsg",IF(AND(ISNA('#_Sheet1'!F6),ISNA(Sheet1!F6)),TRUE,FALSE),"PerfectMsg",IF(NOT(ISERROR('#_Sheet1'!F6)),IF(ISERROR(Sheet1!F6),TRUE,FALSE),FALSE),"StuErrorMsg",IF(TYPE('#_Sheet1'!F6)<>TYPE(Sheet1!F6),TRUE,FALSE),"WrongTypeMsg",IF(ISNUMBER('#_Sheet1'!F6),IF(ABS('#_Sheet1'!F6-Sheet1!F6)>0.00001,TRUE,FALSE),IF('#_Sheet1'!F6<>Sheet1!F6,TRUE,FALSE)),IF(ISNUMBER('#_Sheet1'!F6),IF('#_Sheet1'!F6>Sheet1!F6,"TooLow","TooHigh"),"WrongAnswer"),NOT(_xlfn.ISFORMULA('#_Sheet1'!F6)),IF(_xlfn.IFS(ISTEXT('#_Sheet1'!F6),FALSE,ISLOGICAL('#_Sheet1'!F6),FALSE,SUBSTITUTE(CELL("format",'#_Sheet1'!F6),"-","")=SUBSTITUTE(CELL("format",Sheet1!F6),"-",""),FALSE,CELL("format",'#_Sheet1'!F6)="G",FALSE,AND(CELL("format",'#_Sheet1'!F6)="F0",CELL("format",Sheet1!F6)="G"),FALSE,TRUE,IFERROR(IF(MATCH(CELL("format",'#_Sheet1'!F6),FormatCodesSFX!$A$4:$A$53,0)>0,TRUE),FALSE),TRUE,TRUE),"FormatMsg","PerfectMsg"),_xlfn.IFS(ISTEXT('#_Sheet1'!F6),FALSE,ISLOGICAL('#_Sheet1'!F6),FALSE,SUBSTITUTE(CELL("format",'#_Sheet1'!F6),"-","")=SUBSTITUTE(CELL("format",Sheet1!F6),"-",""),FALSE,CELL("format",'#_Sheet1'!F6)="G",FALSE,AND(CELL("format",'#_Sheet1'!F6)="F0",CELL("format",Sheet1!F6)="G"),FALSE,TRUE,IFERROR(IF(MATCH(CELL("format",'#_Sheet1'!F6),FormatCodesSFX!$A$4:$A$53,0)>0,TRUE),FALSE),TRUE,TRUE),"FormatMsg",TRUE,"PerfectMsg") | G6: =_xlfn.IFS(ISBLANK(Sheet1!G6),"",IF(NOT(ISNA('#_Sheet1'!G6)),IF(ISNA(Sheet1!G6),TRUE,FALSE),FALSE),"StuNAMsg",IF(AND(ISNA('#_Sheet1'!G6),ISNA(Sheet1!G6)),TRUE,FALSE),"PerfectMsg",IF(NOT(ISERROR('#_Sheet1'!G6)),IF(ISERROR(Sheet1!G6),TRUE,FALSE),FALSE),"StuErrorMsg",IF(TYPE('#_Sheet1'!G6)<>TYPE(Sheet1!G6),TRUE,FALSE),"WrongTypeMsg",IF(ISNUMBER('#_Sheet1'!G6),IF(ABS('#_Sheet1'!G6-Sheet1!G6)>0.00001,TRUE,FALSE),IF('#_Sheet1'!G6<>Sheet1!G6,TRUE,FALSE)),IF(ISNUMBER('#_Sheet1'!G6),IF('#_Sheet1'!G6>Sheet1!G6,"TooLow","TooHigh"),"WrongAnswer"),NOT(_xlfn.ISFORMULA('#_Sheet1'!G6)),IF(_xlfn.IFS(ISTEXT('#_Sheet1'!G6),FALSE,ISLOGICAL('#_Sheet1'!G6),FALSE,SUBSTITUTE(CELL("format",'#_Sheet1'!G6),"-","")=SUBSTITUTE(CELL("format",Sheet1!G6),"-",""),FALSE,CELL("format",'#_Sheet1'!G6)="G",FALSE,AND(CELL("format",'#_Sheet1'!G6)="F0",CELL("format",Sheet1!G6)="G"),FALSE,TRUE,IFERROR(IF(MATCH(CELL("format",'#_Sheet1'!G6),FormatCodesSFX!$A$4:$A$53,0)>0,TRUE),FALSE),TRUE,TRUE),"FormatMsg","PerfectMsg"),_xlfn.IFS(ISTEXT('#_Sheet1'!G6),FALSE,ISLOGICAL('#_Sheet1'!G6),FALSE,SUBSTITUTE(CELL("format",'#_Sheet1'!G6),"-","")=SUBSTITUTE(CELL("format",Sheet1!G6),"-",""),FALSE,CELL("format",'#_Sheet1'!G6)="G",FALSE,AND(CELL("format",'#_Sheet1'!G6)="F0",CELL("format",Sheet1!G6)="G"),FALSE,TRUE,IFERROR(IF(MATCH(CELL("format",'#_Sheet1'!G6),FormatCodesSFX!$A$4:$A$53,0)>0,TRUE),FALSE),TRUE,TRUE),"FormatMsg",TRUE,"PerfectMsg") | H6: =_xlfn.IFS(ISBLANK(Sheet1!H6),"",IF(NOT(ISNA('#_Sheet1'!H6)),IF(ISNA(Sheet1!H6),TRUE,FALSE),FALSE),"StuNAMsg",IF(AND(ISNA('#_Sheet1'!H6),ISNA(Sheet1!H6)),TRUE,FALSE),"PerfectMsg",IF(NOT(ISERROR('#_Sheet1'!H6)),IF(ISERROR(Sheet1!H6),TRUE,FALSE),FALSE),"StuErrorMsg",IF(TYPE('#_Sheet1'!H6)<>TYPE(Sheet1!H6),TRUE,FALSE),"WrongTypeMsg",IF(ISNUMBER('#_Sheet1'!H6),IF(ABS('#_Sheet1'!H6-Sheet1!H6)>0.00001,TRUE,FALSE),IF('#_Sheet1'!H6<>Sheet1!H6,TRUE,FALSE)),IF(ISNUMBER('#_Sheet1'!H6),IF('#_Sheet1'!H6>Sheet1!H6,"TooLow","TooHigh"),"WrongAnswer"),NOT(_xlfn.ISFORMULA('#_Sheet1'!H6)),IF(_xlfn.IFS(ISTEXT('#_Sheet1'!H6),FALSE,ISLOGICAL('#_Sheet1'!H6),FALSE,SUBSTITUTE(CELL("format",'#_Sheet1'!H6),"-","")=SUBSTITUTE(CELL("format",Sheet1!H6),"-",""),FALSE,CELL("format",'#_Sheet1'!H6)="G",FALSE,AND(CELL("format",'#_Sheet1'!H6)="F0",CELL("format",Sheet1!H6)="G"),FALSE,TRUE,IFERROR(IF(MATCH(CELL("format",'#_Sheet1'!H6),FormatCodesSFX!$A$4:$A$53,0)>0,TRUE),FALSE),TRUE,TRUE),"FormatMsg","PerfectMsg"),_xlfn.IFS(ISTEXT('#_Sheet1'!H6),FALSE,ISLOGICAL('#_Sheet1'!H6),FALSE,SUBSTITUTE(CELL("format",'#_Sheet1'!H6),"-","")=SUBSTITUTE(CELL("format",Sheet1!H6),"-",""),FALSE,CELL("format",'#_Sheet1'!H6)="G",FALSE,AND(CELL("format",'#_Sheet1'!H6)="F0",CELL("format",Sheet1!H6)="G"),FALSE,TRUE,IFERROR(IF(MATCH(CELL("format",'#_Sheet1'!H6),FormatCodesSFX!$A$4:$A$53,0)>0,TRUE),FALSE),TRUE,TRUE),"FormatMsg",TRUE,"PerfectMsg")
