Workbook

Sheet Pizza Sales Calculations
A1: OrderNumber | B1: OrderPlace | C1: OrderReady | D1: ItemOrdered1 | E1: ItemOrdered2 | F1: ItemOrdered3 | G1: Delivery | H1: DeliveryZipCode | I1: DeliveryDistance | J1: OrderDelivery | K1: TotalPrice(NoTaxes) | L1: DeliveryDuration | M1: NumberofItemsOrdered | N1: WeightItem1 | O1: WeightItem2 | P1: WeightItem3 | Q1: TotalWeightOrder | R1: CostTraditionalDelivery | S1: DroneRange | T1: DroneDeliveryDuration | U1: CostDroneDelivery | V1: PriceItem1 | W1: PriceItem2 | X1: PriceItem3
A2: 1 | B2: 42370.518 | C2: 42370.528 | D2: Small | E2: Medium | G2: FALSE | H2: 70803 | I2: 0 | J2: 42370.53 | K2: 19.58 | L2: =('Pizza Sales Calculations'!$J2-'Pizza Sales Calculations'!$C2)*24*60 -> 2.9666667 | M2: =COUNTA('Pizza Sales Calculations'!$D2:$F2) -> 2 | R2: =IF('Pizza Sales Calculations'!$G2=TRUE, Parameters!$B$17*'Pizza Sales Calculations'!$L2*2, 0) -> 0
A3: 2 | B3: 42370.523 | C3: 42370.534 | D3: Large | G3: FALSE | H3: 70804 | I3: 0 | J3: 42370.536 | K3: 15.35 | L3: =('Pizza Sales Calculations'!$J3-'Pizza Sales Calculations'!$C3)*24*60 -> 2.9666667 | M3: =COUNTA('Pizza Sales Calculations'!$D3:$F3) -> 1 | R3: =IF('Pizza Sales Calculations'!$G3=TRUE, Parameters!$B$17*'Pizza Sales Calculations'!$L3*2, 0) -> 0
A4: 3 | B4: 42370.527 | C4: 42370.537 | D4: Small | E4: Medium | G4: FALSE | H4: 70804 | I4: 0 | J4: 42370.539 | K4: 19.58 | L4: =('Pizza Sales Calculations'!$J4-'Pizza Sales Calculations'!$C4)*24*60 -> 2.9833333 | M4: =COUNTA('Pizza Sales Calculations'!$D4:$F4) -> 2 | R4: =IF('Pizza Sales Calculations'!$G4=TRUE, Parameters!$B$17*'Pizza Sales Calculations'!$L4*2, 0) -> 0
A5: 4 | B5: 42370.493 | C5: 42370.503 | D5: Small | G5: FALSE | H5: 70806 | I5: 0 | J5: 42370.505 | K5: 7.99 | L5: =('Pizza Sales Calculations'!$J5-'Pizza Sales Calculations'!$C5)*24*60 -> 3 | M5: =COUNTA('Pizza Sales Calculations'!$D5:$F5) -> 1 | R5: =IF('Pizza Sales Calculations'!$G5=TRUE, Parameters!$B$17*'Pizza Sales Calculations'!$L5*2, 0) -> 0
A6: 5 | B6: 42370.451 | C6: 42370.461 | D6: Medium | G6: TRUE | H6: 70805 | I6: 2.4793323 | J6: 42370.47 | K6: 11.59 | L6: =('Pizza Sales Calculations'!$J6-'Pizza Sales Calculations'!$C6)*24*60 -> 12.383333 | M6: =COUNTA('Pizza Sales Calculations'!$D6:$F6) -> 1 | R6: =IF('Pizza Sales Calculations'!$G6=TRUE, Parameters!$B$17*'Pizza Sales Calculations'!$L6*2, 0) -> 3.5086111
A7: 6 | B7: 42370.521 | C7: 42370.532 | D7: Small | G7: TRUE | H7: 70803 | I7: 2.3576023 | J7: 42370.54 | K7: 7.99 | L7: =('Pizza Sales Calculations'!$J7-'Pizza Sales Calculations'!$C7)*24*60 -> 11.783333 | M7: =COUNTA('Pizza Sales Calculations'!$D7:$F7) -> 1 | R7: =IF('Pizza Sales Calculations'!$G7=TRUE, Parameters!$B$17*'Pizza Sales Calculations'!$L7*2, 0) -> 3.3386111
A8: 7 | B8: 42370.523 | C8: 42370.533 | D8: Medium | G8: TRUE | H8: 70807 | I8: 2.0571563 | J8: 42370.541 | K8: 11.59 | L8: =('Pizza Sales Calculations'!$J8-'Pizza Sales Calculations'!$C8)*24*60 -> 10.283333 | M8: =COUNTA('Pizza Sales Calculations'!$D8:$F8) -> 1 | R8: =IF('Pizza Sales Calculations'!$G8=TRUE, Parameters!$B$17*'Pizza Sales Calculations'!$L8*2, 0) -> 2.9136111
A9: 8 | B9: 42370.557 | C9: 42370.568 | D9: Small | E9: Medium | G9: TRUE | H9: 70804 | I9: 4.8175175 | J9: 42370.585 | K9: 19.58 | L9: =('Pizza Sales Calculations'!$J9-'Pizza Sales Calculations'!$C9)*24*60 -> 24.083333 | M9: =COUNTA('Pizza Sales Calculations'!$D9:$F9) -> 2 | R9: =IF('Pizza Sales Calculations'!$G9=TRUE, Parameters!$B$17*'Pizza Sales Calculations'!$L9*2, 0) -> 6.8236111
A10: 9 | B10: 42370.488 | C10: 42370.499 | D10: Small | E10: Medium | G10: TRUE | H10: 70803 | I10: 3.1066756 | J10: 42370.51 | K10: 19.58 | L10: =('Pizza Sales Calculations'!$J10-'Pizza Sales Calculations'!$C10)*24*60 -> 15.533333 | M10: =COUNTA('Pizza Sales Calculations'!$D10:$F10) -> 2 | R10: =IF('Pizza Sales Calculations'!$G10=TRUE, Parameters!$B$17*'Pizza Sales Calculations'!$L10*2, 0) -> 4.4011111
A11: 10 | B11: 42370.435 | C11: 42370.445 | D11: Medium | G11: TRUE | H11: 70804 | I11: 4.556016 | J11: 42370.461 | K11: 11.59 | L11: =('Pizza Sales Calculations'!$J11-'Pizza Sales Calculations'!$C11)*24*60 -> 22.766667 | M11: =COUNTA('Pizza Sales Calculations'!$D11:$F11) -> 1 | R11: =IF('Pizza Sales Calculations'!$G11=TRUE, Parameters!$B$17*'Pizza Sales Calculations'!$L11*2, 0) -> 6.4505556
A12: 11 | B12: 42370.514 | C12: 42370.524 | D12: Medium | G12: FALSE | H12: 70804 | I12: 0 | J12: 42370.526 | K12: 11.59 | L12: =('Pizza Sales Calculations'!$J12-'Pizza Sales Calculations'!$C12)*24*60 -> 3 | M12: =COUNTA('Pizza Sales Calculations'!$D12:$F12) -> 1 | R12: =IF('Pizza Sales Calculations'!$G12=TRUE, Parameters!$B$17*'Pizza Sales Calculations'!$L12*2, 0) -> 0
A13: 12 | B13: 42370.523 | C13: 42370.534 | D13: Small | E13: Large | G13: FALSE | H13: 70805 | I13: 0 | J13: 42370.536 | K13: 23.34 | L13: =('Pizza Sales Calculations'!$J13-'Pizza Sales Calculations'!$C13)*24*60 -> 2.9833333 | M13: =COUNTA('Pizza Sales Calculations'!$D13:$F13) -> 2 | R13: =IF('Pizza Sales Calculations'!$G13=TRUE, Parameters!$B$17*'Pizza Sales Calculations'!$L13*2, 0) -> 0
A14: 13 | B14: 42370.482 | C14: 42370.493 | D14: Small | E14: Medium | G14: TRUE | H14: 70806 | I14: 3.1092624 | J14: 42370.504 | K14: 19.58 | L14: =('Pizza Sales Calculations'!$J14-'Pizza Sales Calculations'!$C14)*24*60 -> 15.533333 | M14: =COUNTA('Pizza Sales Calculations'!$D14:$F14) -> 2 | R14: =IF('Pizza Sales Calculations'!$G14=TRUE, Parameters!$B$17*'Pizza Sales Calculations'!$L14*2, 0) -> 4.4011111
A15: 14 | B15: 42370.51 | C15: 42370.521 | D15: Small | G15: FALSE | H15: 70804 | I15: 0 | J15: 42370.523 | K15: 7.99 | L15: =('Pizza Sales Calculations'!$J15-'Pizza Sales Calculations'!$C15)*24*60 -> 3 | M15: =COUNTA('Pizza Sales Calculations'!$D15:$F15) -> 1 | R15: =IF('Pizza Sales Calculations'!$G15=TRUE, Parameters!$B$17*'Pizza Sales Calculations'!$L15*2, 0) -> 0
A16: 15 | B16: 42370.529 | C16: 42370.539 | D16: Medium | G16: FALSE | H16: 70803 | I16: 0 | J16: 42370.541 | K16: 11.59 | L16: =('Pizza Sales Calculations'!$J16-'Pizza Sales Calculations'!$C16)*24*60 -> 2.9833333 | M16: =COUNTA('Pizza Sales Calculations'!$D16:$F16) -> 1 | R16: =IF('Pizza Sales Calculations'!$G16=TRUE, Parameters!$B$17*'Pizza Sales Calculations'!$L16*2, 0) -> 0
A17: 16 | B17: 42370.497 | C17: 42370.507 | D17: Small | E17: Medium | G17: TRUE | H17: 70806 | I17: 3.4135037 | J17: 42370.519 | K17: 19.58 | L17: =('Pizza Sales Calculations'!$J17-'Pizza Sales Calculations'!$C17)*24*60 -> 17.066667 | M17: =COUNTA('Pizza Sales Calculations'!$D17:$F17) -> 2 | R17: =IF('Pizza Sales Calculations'!$G17=TRUE, Parameters!$B$17*'Pizza Sales Calculations'!$L17*2, 0) -> 4.8355556
A18: 17 | B18: 42370.576 | C18: 42370.586 | D18: Medium | G18: TRUE | H18: 70806 | I18: 2.5641446 | J18: 42370.595 | K18: 11.59 | L18: =('Pizza Sales Calculations'!$J18-'Pizza Sales Calculations'!$C18)*24*60 -> 12.816667 | M18: =COUNTA('Pizza Sales Calculations'!$D18:$F18) -> 1 | R18: =IF('Pizza Sales Calculations'!$G18=TRUE, Parameters!$B$17*'Pizza Sales Calculations'!$L18*2, 0) -> 3.6313889
A19: 18 | B19: 42370.52 | C19: 42370.53 | D19: Medium | G19: TRUE | H19: 70803 | I19: 4.4542172 | J19: 42370.546 | K19: 11.59 | L19: =('Pizza Sales Calculations'!$J19-'Pizza Sales Calculations'!$C19)*24*60 -> 22.266667 | M19: =COUNTA('Pizza Sales Calculations'!$D19:$F19) -> 1 | R19: =IF('Pizza Sales Calculations'!$G19=TRUE, Parameters!$B$17*'Pizza Sales Calculations'!$L19*2, 0) -> 6.3088889
A20: 19 | B20: 42370.531 | C20: 42370.542 | D20: Large | G20: TRUE | H20: 70803 | I20: 4.1472808 | J20: 42370.556 | K20: 15.35 | L20: =('Pizza Sales Calculations'!$J20-'Pizza Sales Calculations'!$C20)*24*60 -> 20.733333 | M20: =COUNTA('Pizza Sales Calculations'!$D20:$F20) -> 1 | R20: =IF('Pizza Sales Calculations'!$G20=TRUE, Parameters!$B$17*'Pizza Sales Calculations'!$L20*2, 0) -> 5.8744444
A21: 20 | B21: 42370.494 | C21: 42370.505 | D21: Large | G21: FALSE | H21: 70807 | I21: 0 | J21: 42370.507 | K21: 15.35 | L21: =('Pizza Sales Calculations'!$J21-'Pizza Sales Calculations'!$C21)*24*60 -> 3.0166667 | M21: =COUNTA('Pizza Sales Calculations'!$D21:$F21) -> 1 | R21: =IF('Pizza Sales Calculations'!$G21=TRUE, Parameters!$B$17*'Pizza Sales Calculations'!$L21*2, 0) -> 0
A22: 21 | B22: 42370.431 | C22: 42370.441 | D22: Medium | G22: TRUE | H22: 70804 | I22: 2.0976294 | J22: 42370.448 | K22: 11.59 | L22: =('Pizza Sales Calculations'!$J22-'Pizza Sales Calculations'!$C22)*24*60 -> 10.483333 | M22: =COUNTA('Pizza Sales Calculations'!$D22:$F22) -> 1 | R22: =IF('Pizza Sales Calculations'!$G22=TRUE, Parameters!$B$17*'Pizza Sales Calculations'!$L22*2, 0) -> 2.9702778
A23: 22 | B23: 42370.426 | C23: 42370.436 | D23: Small | G23: FALSE | H23: 70805 | I23: 0 | J23: 42370.438 | K23: 7.99 | L23: =('Pizza Sales Calculations'!$J23-'Pizza Sales Calculations'!$C23)*24*60 -> 3.0166667 | M23: =COUNTA('Pizza Sales Calculations'!$D23:$F23) -> 1 | R23: =IF('Pizza Sales Calculations'!$G23=TRUE, Parameters!$B$17*'Pizza Sales Calculations'!$L23*2, 0) -> 0
A24: 23 | B24: 42370.528 | C24: 42370.539 | D24: Large | G24: TRUE | H24: 70805 | I24: 2.5751773 | J24: 42370.548 | K24: 15.35 | L24: =('Pizza Sales Calculations'!$J24-'Pizza Sales Calculations'!$C24)*24*60 -> 12.866667 | M24: =COUNTA('Pizza Sales Calculations'!$D24:$F24) -> 1 | R24: =IF('Pizza Sales Calculations'!$G24=TRUE, Parameters!$B$17*'Pizza Sales Calculations'!$L24*2, 0) -> 3.6455556
A25: 24 | B25: 42370.525 | C25: 42370.536 | D25: Medium | G25: TRUE | H25: 70804 | I25: 4.1683095 | J25: 42370.55 | K25: 11.59 | L25: =('Pizza Sales Calculations'!$J25-'Pizza Sales Calculations'!$C25)*24*60 -> 20.833333 | M25: =COUNTA('Pizza Sales Calculations'!$D25:$F25) -> 1 | R25: =IF('Pizza Sales Calculations'!$G25=TRUE, Parameters!$B$17*'Pizza Sales Calculations'!$L25*2, 0) -> 5.9027778
A26: 25 | B26: 42370.439 | C26: 42370.449 | D26: Medium | E26: Large | G26: TRUE | H26: 70804 | I26: 1.9678453 | J26: 42370.456 | K26: 25.94 | L26: =('Pizza Sales Calculations'!$J26-'Pizza Sales Calculations'!$C26)*24*60 -> 9.8333333 | M26: =COUNTA('Pizza Sales Calculations'!$D26:$F26) -> 2 | R26: =IF('Pizza Sales Calculations'!$G26=TRUE, Parameters!$B$17*'Pizza Sales Calculations'!$L26*2, 0) -> 2.7861111
A27: 26 | B27: 42370.471 | C27: 42370.482 | D27: Small | E27: Large | G27: FALSE | H27: 70807 | I27: 0 | J27: 42370.484 | K27: 23.34 | L27: =('Pizza Sales Calculations'!$J27-'Pizza Sales Calculations'!$C27)*24*60 -> 2.9666667 | M27: =COUNTA('Pizza Sales Calculations'!$D27:$F27) -> 2 | R27: =IF('Pizza Sales Calculations'!$G27=TRUE, Parameters!$B$17*'Pizza Sales Calculations'!$L27*2, 0) -> 0
A28: 27 | B28: 42371.523 | C28: 42371.533 | D28: Small | E28: Medium | G28: TRUE | H28: 70806 | I28: 3.6126489 | J28: 42371.546 | K28: 19.58 | L28: =('Pizza Sales Calculations'!$J28-'Pizza Sales Calculations'!$C28)*24*60 -> 18.05 | M28: =COUNTA('Pizza Sales Calculations'!$D28:$F28) -> 2 | R28: =IF('Pizza Sales Calculations'!$G28=TRUE, Parameters!$B$17*'Pizza Sales Calculations'!$L28*2, 0) -> 5.1141667
A29: 28 | B29: 42371.508 | C29: 42371.519 | D29: Small | G29: FALSE | H29: 70803 | I29: 0 | J29: 42371.521 | K29: 7.99 | L29: =('Pizza Sales Calculations'!$J29-'Pizza Sales Calculations'!$C29)*24*60 -> 3 | M29: =COUNTA('Pizza Sales Calculations'!$D29:$F29) -> 1 | R29: =IF('Pizza Sales Calculations'!$G29=TRUE, Parameters!$B$17*'Pizza Sales Calculations'!$L29*2, 0) -> 0
A30: 29 | B30: 42371.459 | C30: 42371.469 | D30: Large | G30: FALSE | H30: 70805 | I30: 0 | J30: 42371.471 | K30: 15.35 | L30: =('Pizza Sales Calculations'!$J30-'Pizza Sales Calculations'!$C30)*24*60 -> 2.9833333 | M30: =COUNTA('Pizza Sales Calculations'!$D30:$F30) -> 1 | R30: =IF('Pizza Sales Calculations'!$G30=TRUE, Parameters!$B$17*'Pizza Sales Calculations'!$L30*2, 0) -> 0
A31: 30 | B31: 42371.549 | C31: 42371.559 | D31: Medium | G31: TRUE | H31: 70805 | I31: 2.9869999 | J31: 42371.57 | K31: 11.59 | L31: =('Pizza Sales Calculations'!$J31-'Pizza Sales Calculations'!$C31)*24*60 -> 14.933333 | M31: =COUNTA('Pizza Sales Calculations'!$D31:$F31) -> 1 | R31: =IF('Pizza Sales Calculations'!$G31=TRUE, Parameters!$B$17*'Pizza Sales Calculations'!$L31*2, 0) -> 4.2311111
A32: 31 | B32: 42371.513 | C32: 42371.523 | D32: Large | G32: FALSE | H32: 70804 | I32: 0 | J32: 42371.525 | K32: 15.35 | L32: =('Pizza Sales Calculations'!$J32-'Pizza Sales Calculations'!$C32)*24*60 -> 2.95 | M32: =COUNTA('Pizza Sales Calculations'!$D32:$F32) -> 1 | R32: =IF('Pizza Sales Calculations'!$G32=TRUE, Parameters!$B$17*'Pizza Sales Calculations'!$L32*2, 0) -> 0
A33: 32 | B33: 42371.523 | C33: 42371.534 | D33: Medium | G33: TRUE | H33: 70805 | I33: 1.8750196 | J33: 42371.54 | K33: 11.59 | L33: =('Pizza Sales Calculations'!$J33-'Pizza Sales Calculations'!$C33)*24*60 -> 9.3666667 | M33: =COUNTA('Pizza Sales Calculations'!$D33:$F33) -> 1 | R33: =IF('Pizza Sales Calculations'!$G33=TRUE, Parameters!$B$17*'Pizza Sales Calculations'!$L33*2, 0) -> 2.6538889
A34: 33 | B34: 42371.431 | C34: 42371.442 | D34: Large | G34: FALSE | H34: 70804 | I34: 0 | J34: 42371.444 | K34: 15.35 | L34: =('Pizza Sales Calculations'!$J34-'Pizza Sales Calculations'!$C34)*24*60 -> 2.9833333 | M34: =COUNTA('Pizza Sales Calculations'!$D34:$F34) -> 1 | R34: =IF('Pizza Sales Calculations'!$G34=TRUE, Parameters!$B$17*'Pizza Sales Calculations'!$L34*2, 0) -> 0
A35: 34 | B35: 42371.466 | C35: 42371.477 | D35: Small | E35: Medium | G35: TRUE | H35: 70803 | I35: 2.6679713 | J35: 42371.486 | K35: 19.58 | L35: =('Pizza Sales Calculations'!$J35-'Pizza Sales Calculations'!$C35)*24*60 -> 13.333333 | M35: =COUNTA('Pizza Sales Calculations'!$D35:$F35) -> 2 | R35: =IF('Pizza Sales Calculations'!$G35=TRUE, Parameters!$B$17*'Pizza Sales Calculations'!$L35*2, 0) -> 3.7777778
A36: 35 | B36: 42371.537 | C36: 42371.548 | D36: Medium | G36: FALSE | H36: 70806 | I36: 0 | J36: 42371.55 | K36: 11.59 | L36: =('Pizza Sales Calculations'!$J36-'Pizza Sales Calculations'!$C36)*24*60 -> 2.9833333 | M36: =COUNTA('Pizza Sales Calculations'!$D36:$F36) -> 1 | R36: =IF('Pizza Sales Calculations'!$G36=TRUE, Parameters!$B$17*'Pizza Sales Calculations'!$L36*2, 0) -> 0
A37: 36 | B37: 42371.48 | C37: 42371.49 | D37: Large | G37: TRUE | H37: 70805 | I37: 3.9470079 | J37: 42371.504 | K37: 15.35 | L37: =('Pizza Sales Calculations'!$J37-'Pizza Sales Calculations'!$C37)*24*60 -> 19.733333 | M37: =COUNTA('Pizza Sales Calculations'!$D37:$F37) -> 1 | R37: =IF('Pizza Sales Calculations'!$G37=TRUE, Parameters!$B$17*'Pizza Sales Calculations'!$L37*2, 0) -> 5.5911111
A38: 37 | B38: 42371.54 | C38: 42371.55 | D38: Small | G38: TRUE | H38: 70805 | I38: 2.2604541 | J38: 42371.558 | K38: 7.99 | L38: =('Pizza Sales Calculations'!$J38-'Pizza Sales Calculations'!$C38)*24*60 -> 11.3 | M38: =COUNTA('Pizza Sales Calculations'!$D38:$F38) -> 1 | R38: =IF('Pizza Sales Calculations'!$G38=TRUE, Parameters!$B$17*'Pizza Sales Calculations'!$L38*2, 0) -> 3.2016667
A39: 38 | B39: 42371.466 | C39: 42371.477 | D39: Medium | G39: TRUE | H39: 70807 | I39: 3.8581374 | J39: 42371.49 | K39: 11.59 | L39: =('Pizza Sales Calculations'!$J39-'Pizza Sales Calculations'!$C39)*24*60 -> 19.283333 | M39: =COUNTA('Pizza Sales Calculations'!$D39:$F39) -> 1 | R39: =IF('Pizza Sales Calculations'!$G39=TRUE, Parameters!$B$17*'Pizza Sales Calculations'!$L39*2, 0) -> 5.4636111
A40: 39 | B40: 42371.514 | C40: 42371.525 | D40: Large | G40: TRUE | H40: 70805 | I40: 2.3749016 | J40: 42371.533 | K40: 15.35 | L40: =('Pizza Sales Calculations'!$J40-'Pizza Sales Calculations'!$C40)*24*60 -> 11.866667 | M40: =COUNTA('Pizza Sales Calculations'!$D40:$F40) -> 1 | R40: =IF('Pizza Sales Calculations'!$G40=TRUE, Parameters!$B$17*'Pizza Sales Calculations'!$L40*2, 0) -> 3.3622222
...

Sheet Parameters
A2: Pizza size | B2: Avg Price | C2: Avg Weight (lbs)
A3: Small | B3: 7 | C3: 1
A4: Medium | B4: 10 | C4: 1.7
A5: Large | B5: 14 | C5: 2.3
A7: Working hours per day | B7: 6
A8: Avg distance delivery for drone elegible deliveries
A9: Drone elegible number of deliveries
A10: Years drone depreciation | B10: 3
A13: Traditional delivery economics | B13: (http://www.pizzatoday.com/departments/back-office/cost-of-delivery/)
A14: Hourly wage (considering SS, Medicare) | B14: =7+1 -> 8
A15: Non-Owned auto insurance and meals / h | B15: 0.5
A16: Delivery cost charged to customer | B16: 2
A17: Cost per minute | B17: =(B14+B15)/60 -> 0.14166667
A20: Drone Characteristics | B20: (http://drones.specout.com/l/1125/DJI-Matrice-600-Pro-M600-Pro) | H20: Alternative (http://drones.specout.com/l/111/Yuneec-Flying-Eyes-HX3)
A21: Operating range (miles) | B21: 3.2
A22: Flight time autonomy (min) | B22: 32
A23: Payload capacity (pounds) | B23: 13.23
A24: Max speed (mph) | B24: 38
A25: Avg speed (mph) | B25: 30
A26: Price | B26: 5000
A27: Maintenance per year | B27: 500
A29: Average time to deliver drone / h | B29: =(B8*2)/B25 -> 0
A30: Maximum drone deliveries per hour | B30: =1/B29 -> #DIV/0!
A33: Pizza drone
A34: Hourly wage drone operator | B34: 10
A35: Number of drones per operator | B35: 12
A36: Electricity per minute | B36: =0.05/60 -> 0.00083333333
A38: Cost per minute operator + electricity | B38: =((B34/B35)/60)+B36 -> 0.014722222
A39: Cost drone per minute | B39: =((B26/3)+B27)/365/B7/60 -> 0.016489092
A40: Total cost drone per minute | B40: =B38+B39 -> 0.031211314
A42: Average orders per day | B42: 100
A43: % Total order elegible for drone delivery
A44: Avg cost traditional delivery (drone eligible)
A45: Avg cost drone delivery
